File: data_clean.csv
, C, Si, Mn, P, S, Ni, Cr, Mo, Cu,V, Al, N,Ceq,Nb + Ta, Temperature (Â°C), 0.2% Proof Stress (MPa), Tensile Strength (MPa), Elongation (%), Reduction in Area (%)
0,0.12,0.36,0.52,0.009,0.003,0.089,0.97,0.61,0.2,0.0,-5.809142990314028,0.0066,0.0,0.0,27,342,490,3.4011973816621555,71
3,0.12,0.36,0.52,0.009,0.003,0.089,0.97,0.61,0.2,0.0,-5.809142990314028,0.0066,0.0,0.0,300,346,495,3.044522437723423,70
6,0.12,0.36,0.52,0.009,0.003,0.089,0.97,0.61,0.2,0.0,-5.809142990314028,0.0066,0.0,0.0,500,274,431,3.332204510175204,85
9,0.12,0.36,0.52,0.009,0.003,0.089,0.97,0.61,0.2,0.0,-5.809142990314028,0.0066,0.0,0.0,650,152,226,4.07753744390572,92
12,0.09,0.37,0.49,0.006,0.005,0.055,0.98,0.57,0.2645751311064591,0.0,-5.298317366548036,0.008,0.0,0.0,200,296,439,3.2188758248682006,77
15,0.09,0.37,0.49,0.006,0.005,0.055,0.98,0.57,0.2645751311064591,0.0,-5.298317366548036,0.008,0.0,0.0,450,240,451,3.258096538021482,80
18,0.09,0.37,0.49,0.006,0.005,0.055,0.98,0.57,0.2645751311064591,0.0,-5.298317366548036,0.008,0.0,0.0,600,176,297,3.784189633918261,89
21,0.1,0.28,0.49,0.008,0.009,0.028,0.9,0.56,0.282842712474619,0.0,-5.115995809754082,0.009,0.0,0.0,100,258,432,3.258096538021482,76
24,0.1,0.28,0.49,0.008,0.009,0.028,0.9,0.56,0.282842712474619,0.0,-5.115995809754082,0.009,0.0,0.0,400,264,464,3.2188758248682006,75
27,0.1,0.28,0.49,0.008,0.009,0.028,0.9,0.56,0.282842712474619,0.0,-5.115995809754082,0.009,0.0,0.0,550,228,378,3.332204510175204,84
30,0.12,0.43,0.48,0.014,0.008,0.051,0.96,0.56,0.282842712474619,0.0,-5.115995809754082,0.008,0.0,0.0,27,343,502,3.4657359027997265,76
33,0.12,0.43,0.48,0.014,0.008,0.051,0.96,0.56,0.282842712474619,0.0,-5.115995809754082,0.008,0.0,0.0,300,277,505,3.091042453358316,67
36,0.12,0.43,0.48,0.014,0.008,0.051,0.96,0.56,0.282842712474619,0.0,-5.115995809754082,0.008,0.0,0.0,500,255,434,3.1780538303479458,81
39,0.12,0.43,0.48,0.014,0.008,0.051,0.96,0.56,0.282842712474619,0.0,-5.115995809754082,0.008,0.0,0.0,650,143,221,3.9318256327243257,91
42,0.12,0.28,0.44,0.018,0.008,0.03,0.99,0.54,0.282842712474619,0.0,-4.961845129926823,0.01,0.0,0.0,200,315,475,3.1354942159291497,72
45,0.12,0.28,0.44,0.018,0.008,0.03,0.99,0.54,0.282842712474619,0.0,-4.961845129926823,0.01,0.0,0.0,450,256,465,3.2188758248682006,77
48,0.12,0.28,0.44,0.018,0.008,0.03,0.99,0.54,0.282842712474619,0.0,-4.961845129926823,0.01,0.0,0.0,600,213,308,3.6109179126442243,89
51,0.12,0.37,0.45,0.018,0.008,0.035,1.0,0.5,0.2449489742783178,0.0,-4.710530701645918,0.0088,0.0,0.0,100,240,420,3.4011973816621555,73
54,0.12,0.37,0.45,0.018,0.008,0.035,1.0,0.5,0.2449489742783178,0.0,-4.710530701645918,0.0088,0.0,0.0,400,192,482,3.295836866004329,76
57,0.12,0.37,0.45,0.018,0.008,0.035,1.0,0.5,0.2449489742783178,0.0,-4.710530701645918,0.0088,0.0,0.0,550,177,375,3.4011973816621555,85
60,0.12,0.36,0.45,0.018,0.007,0.028,1.0,0.53,0.22360679774997896,0.0,-4.961845129926823,0.008,0.0,0.0,27,239,453,3.5553480614894135,72
63,0.12,0.36,0.45,0.018,0.007,0.028,1.0,0.53,0.22360679774997896,0.0,-4.961845129926823,0.008,0.0,0.0,300,210,485,3.1354942159291497,69
66,0.12,0.36,0.45,0.018,0.007,0.028,1.0,0.53,0.22360679774997896,0.0,-4.961845129926823,0.008,0.0,0.0,500,181,434,3.258096538021482,82
69,0.12,0.36,0.45,0.018,0.007,0.028,1.0,0.53,0.22360679774997896,0.0,-4.961845129926823,0.008,0.0,0.0,650,124,214,3.9889840465642745,93
72,0.1,0.35,0.44,0.02,0.007,0.05,1.01,0.51,0.282842712474619,0.0,-4.422848629194137,0.0082,0.0,0.0,200,243,431,3.1780538303479458,72
75,0.1,0.35,0.44,0.02,0.007,0.05,1.01,0.51,0.282842712474619,0.0,-4.422848629194137,0.0082,0.0,0.0,450,176,444,3.258096538021482,76
78,0.1,0.35,0.44,0.02,0.007,0.05,1.01,0.51,0.282842712474619,0.0,-4.422848629194137,0.0082,0.0,0.0,600,161,293,3.6375861597263857,88
81,0.09,0.32,0.48,0.02,0.017,0.023,1.05,0.52,0.2,0.0,-4.710530701645918,0.0089,0.0,0.0,100,301,421,3.1354942159291497,70
84,0.09,0.32,0.48,0.02,0.017,0.023,1.05,0.52,0.2,0.0,-4.710530701645918,0.0089,0.0,0.0,400,279,482,3.1780538303479458,71
87,0.09,0.32,0.48,0.02,0.017,0.023,1.05,0.52,0.2,0.0,-4.710530701645918,0.0089,0.0,0.0,550,251,395,3.295836866004329,82
90,0.1,0.31,0.51,0.022,0.017,0.02,1.03,0.53,0.2,0.0,-4.710530701645918,0.0076,0.0,0.0,27,291,462,3.4011973816621555,71
93,0.1,0.31,0.51,0.022,0.017,0.02,1.03,0.53,0.2,0.0,-4.710530701645918,0.0076,0.0,0.0,300,288,479,3.091042453358316,63
96,0.1,0.31,0.51,0.022,0.017,0.02,1.03,0.53,0.2,0.0,-4.710530701645918,0.0076,0.0,0.0,500,256,441,3.1354942159291497,77
99,0.1,0.31,0.51,0.022,0.017,0.02,1.03,0.53,0.2,0.0,-4.710530701645918,0.0076,0.0,0.0,650,136,217,3.9512437185814275,90
102,0.1,0.3,0.49,0.02,0.018,0.023,1.04,0.5,0.2,0.0,-4.710530701645918,0.0089,0.0,0.0,200,311,454,3.091042453358316,64
105,0.1,0.3,0.49,0.02,0.018,0.023,1.04,0.5,0.2,0.0,-4.710530701645918,0.0089,0.0,0.0,450,280,479,3.1354942159291497,72
108,0.1,0.3,0.49,0.02,0.018,0.023,1.04,0.5,0.2,0.0,-4.710530701645918,0.0089,0.0,0.0,600,215,304,3.5263605246161616,86
111,0.2,0.31,0.59,0.018,0.009,0.0,0.046,0.011,0.22360679774997896,0.0,-5.115995809754082,0.0056,0.0,0.0,100,270,471,3.044522437723423,57
114,0.2,0.31,0.59,0.018,0.009,0.0,0.046,0.011,0.22360679774997896,0.0,-5.115995809754082,0.0056,0.0,0.0,350,185,509,3.5263605246161616,66
117,0.2,0.31,0.59,0.018,0.009,0.0,0.046,0.011,0.22360679774997896,0.0,-5.115995809754082,0.0056,0.0,0.0,500,156,306,3.8066624897703196,82
120,0.2,0.28,0.6,0.018,0.008,0.0,0.045,0.01,0.22360679774997896,0.0,-5.298317366548036,0.0066,0.0,0.0,100,278,456,3.091042453358316,60
123,0.2,0.28,0.6,0.018,0.008,0.0,0.045,0.01,0.22360679774997896,0.0,-5.298317366548036,0.0066,0.0,0.0,350,188,500,3.4657359027997265,65
126,0.2,0.28,0.6,0.018,0.008,0.0,0.045,0.01,0.22360679774997896,0.0,-5.298317366548036,0.0066,0.0,0.0,500,152,302,3.6888794541139363,83
129,0.2,0.29,0.55,0.021,0.009,0.0,0.054,0.012,0.22360679774997896,0.0,-5.521460917862246,0.0058,0.0,0.0,100,271,453,3.091042453358316,60
132,0.2,0.29,0.55,0.021,0.009,0.0,0.054,0.012,0.22360679774997896,0.0,-5.521460917862246,0.0058,0.0,0.0,350,184,485,3.5553480614894135,66
135,0.2,0.29,0.55,0.021,0.009,0.0,0.054,0.012,0.22360679774997896,0.0,-5.521460917862246,0.0058,0.0,0.0,500,165,309,3.713572066704308,83
138,0.21,0.21,0.62,0.014,0.014,0.0,0.046,0.019,0.22360679774997896,0.0,-4.8283137373023015,0.003,0.0,0.0,100,276,456,3.1354942159291497,63
141,0.21,0.21,0.62,0.014,0.014,0.0,0.046,0.019,0.22360679774997896,0.0,-4.8283137373023015,0.003,0.0,0.0,350,197,495,3.4657359027997265,65
144,0.21,0.21,0.62,0.014,0.014,0.0,0.046,0.019,0.22360679774997896,0.0,-4.8283137373023015,0.003,0.0,0.0,500,173,319,3.6375861597263857,78
147,0.24,0.24,0.64,0.015,0.013,0.0,0.074,0.019,0.22360679774997896,0.0,-4.509860006183766,0.006,0.0,0.0,100,291,471,3.1780538303479458,63
150,0.24,0.24,0.64,0.015,0.013,0.0,0.074,0.019,0.22360679774997896,0.0,-4.509860006183766,0.006,0.0,0.0,350,231,506,3.5263605246161616,67
153,0.24,0.24,0.64,0.015,0.013,0.0,0.074,0.019,0.22360679774997896,0.0,-4.509860006183766,0.006,0.0,0.0,500,199,335,3.6375861597263857,79
156,0.2,0.2,0.47,0.007,0.009,0.0,0.056,0.01,0.2645751311064591,0.0,-5.298317366548036,0.011,0.0,0.0,100,297,510,2.9444389791664403,51
159,0.2,0.2,0.47,0.007,0.009,0.0,0.056,0.01,0.2645751311064591,0.0,-5.298317366548036,0.011,0.0,0.0,350,187,497,3.5553480614894135,61
162,0.2,0.2,0.47,0.007,0.009,0.0,0.056,0.01,0.2645751311064591,0.0,-5.298317366548036,0.011,0.0,0.0,500,164,273,3.5553480614894135,68
165,0.21,0.32,0.48,0.02,0.018,0.0,0.017,0.006,0.282842712474619,0.0,-5.521460917862246,0.0044,0.0,0.0,100,260,439,3.2188758248682006,62
168,0.21,0.32,0.48,0.02,0.018,0.0,0.017,0.006,0.282842712474619,0.0,-5.521460917862246,0.0044,0.0,0.0,350,188,469,3.4657359027997265,67
171,0.21,0.32,0.48,0.02,0.018,0.0,0.017,0.006,0.282842712474619,0.0,-5.521460917862246,0.0044,0.0,0.0,500,154,275,3.871201010907891,83
174,0.2,0.31,0.5,0.022,0.017,0.0,0.017,0.006,0.3,0.0,-5.521460917862246,0.0037,0.0,0.0,100,244,434,3.1780538303479458,63
177,0.2,0.31,0.5,0.022,0.017,0.0,0.017,0.006,0.3,0.0,-5.521460917862246,0.0037,0.0,0.0,350,195,472,3.6109179126442243,65
180,0.2,0.31,0.5,0.022,0.017,0.0,0.017,0.006,0.3,0.0,-5.521460917862246,0.0037,0.0,0.0,500,160,276,3.7376696182833684,84
183,0.23,0.32,0.53,0.023,0.016,0.0,0.022,0.005,0.2645751311064591,0.0,-5.298317366548036,0.0051,0.0,0.0,100,267,446,3.2188758248682006,64
186,0.23,0.32,0.53,0.023,0.016,0.0,0.022,0.005,0.2645751311064591,0.0,-5.298317366548036,0.0051,0.0,0.0,350,190,471,3.5553480614894135,65
189,0.23,0.32,0.53,0.023,0.016,0.0,0.022,0.005,0.2645751311064591,0.0,-5.298317366548036,0.0051,0.0,0.0,500,171,286,3.871201010907891,81
192,0.11,0.3,0.48,0.012,0.01,0.0,0.0,0.51,0.0,0.0,-5.298317366548036,0.0078,0.0,0.0,100,260,442,3.258096538021482,67
195,0.11,0.3,0.48,0.012,0.01,0.0,0.0,0.51,0.0,0.0,-5.298317366548036,0.0078,0.0,0.0,400,195,493,3.4011973816621555,74
198,0.11,0.3,0.48,0.012,0.01,0.0,0.0,0.51,0.0,0.0,-5.298317366548036,0.0078,0.0,0.0,550,183,363,3.4657359027997265,83
201,0.12,0.25,0.5,0.012,0.01,0.0,0.0,0.5,0.0,0.0,-5.298317366548036,0.0068,0.0,0.0,100,260,450,3.2188758248682006,65
204,0.12,0.25,0.5,0.012,0.01,0.0,0.0,0.5,0.0,0.0,-5.298317366548036,0.0068,0.0,0.0,400,204,484,3.4339872044851463,73
207,0.12,0.25,0.5,0.012,0.01,0.0,0.0,0.5,0.0,0.0,-5.298317366548036,0.0068,0.0,0.0,550,185,349,3.4011973816621555,85
210,0.13,0.31,0.48,0.006,0.007,0.0,0.0,0.49,0.0,0.0,-5.298317366548036,0.006,0.0,0.0,100,248,439,3.1780538303479458,66
213,0.13,0.31,0.48,0.006,0.007,0.0,0.0,0.49,0.0,0.0,-5.298317366548036,0.006,0.0,0.0,400,173,488,3.4011973816621555,73
216,0.13,0.31,0.48,0.006,0.007,0.0,0.0,0.49,0.0,0.0,-5.298317366548036,0.006,0.0,0.0,550,193,353,3.4657359027997265,84
219,0.15,0.22,0.43,0.011,0.022,0.01,0.02,0.5,0.17320508075688773,0.0,-5.521460917862246,0.004,0.0,0.0,100,260,417,3.1354942159291497,67
222,0.15,0.22,0.43,0.011,0.022,0.01,0.02,0.5,0.17320508075688773,0.0,-5.521460917862246,0.004,0.0,0.0,400,181,428,3.4339872044851463,68
225,0.15,0.22,0.43,0.011,0.022,0.01,0.02,0.5,0.17320508075688773,0.0,-5.521460917862246,0.004,0.0,0.0,550,179,315,3.5553480614894135,82
228,0.14,0.22,0.46,0.012,0.012,0.01,0.03,0.5,0.17320508075688773,0.0,-5.115995809754082,0.006,0.0,0.0,100,274,423,3.044522437723423,67
231,0.14,0.22,0.46,0.012,0.012,0.01,0.03,0.5,0.17320508075688773,0.0,-5.115995809754082,0.006,0.0,0.0,400,262,442,3.4011973816621555,69
234,0.14,0.22,0.46,0.012,0.012,0.01,0.03,0.5,0.17320508075688773,0.0,-5.115995809754082,0.006,0.0,0.0,550,213,311,3.4011973816621555,82
237,0.15,0.25,0.58,0.008,0.01,0.05,0.11,0.52,0.2,0.0,-4.961845129926823,0.011,0.0,0.0,100,267,414,3.4011973816621555,72
240,0.15,0.25,0.58,0.008,0.01,0.05,0.11,0.52,0.2,0.0,-4.961845129926823,0.011,0.0,0.0,400,182,438,3.4657359027997265,73
243,0.15,0.25,0.58,0.008,0.01,0.05,0.11,0.52,0.2,0.0,-4.961845129926823,0.011,0.0,0.0,550,175,313,3.6109179126442243,83
246,0.2,0.28,0.59,0.012,0.01,0.02,0.02,0.54,0.2645751311064591,0.0,-5.809142990314028,0.0054,0.0,0.0,100,308,445,2.995732273553991,59
249,0.2,0.28,0.59,0.012,0.01,0.02,0.02,0.54,0.2645751311064591,0.0,-5.809142990314028,0.0054,0.0,0.0,400,252,456,3.332204510175204,65
252,0.2,0.28,0.59,0.012,0.01,0.02,0.02,0.54,0.2645751311064591,0.0,-5.809142990314028,0.0054,0.0,0.0,550,237,321,3.4011973816621555,84
255,0.17,0.3,0.63,0.012,0.012,0.04,0.09,0.52,0.31622776601683794,0.0,-5.809142990314028,0.007,0.0,0.0,100,304,469,2.9444389791664403,57
258,0.17,0.3,0.63,0.012,0.012,0.04,0.09,0.52,0.31622776601683794,0.0,-5.809142990314028,0.007,0.0,0.0,400,238,487,3.295836866004329,61
261,0.17,0.3,0.63,0.012,0.012,0.04,0.09,0.52,0.31622776601683794,0.0,-5.809142990314028,0.007,0.0,0.0,550,219,330,3.5553480614894135,83
264,0.13,0.23,0.66,0.01,0.01,0.08,0.06,0.51,0.36055512754639896,0.0,-5.521460917862246,0.0057,0.0,0.0,100,408,512,2.995732273553991,64
267,0.13,0.23,0.66,0.01,0.01,0.08,0.06,0.51,0.36055512754639896,0.0,-5.521460917862246,0.0057,0.0,0.0,400,237,441,3.295836866004329,65
270,0.13,0.23,0.66,0.01,0.01,0.08,0.06,0.51,0.36055512754639896,0.0,-5.521460917862246,0.0057,0.0,0.0,550,215,317,3.4657359027997265,81
273,0.14,0.39,0.63,0.008,0.005,0.0,0.0,0.58,0.17320508075688773,0.0,-5.521460917862246,0.006,0.0,0.0,100,324,437,2.833213344056216,59
276,0.14,0.39,0.63,0.008,0.005,0.0,0.0,0.58,0.17320508075688773,0.0,-5.521460917862246,0.006,0.0,0.0,400,367,532,3.258096538021482,64
279,0.14,0.39,0.63,0.008,0.005,0.0,0.0,0.58,0.17320508075688773,0.0,-5.521460917862246,0.006,0.0,0.0,550,276,364,3.367295829986474,84
282,0.14,0.4,0.67,0.007,0.004,0.0,0.0,0.6,0.17320508075688773,0.0,-5.521460917862246,0.007,0.0,0.0,100,380,506,2.9444389791664403,61
285,0.14,0.4,0.67,0.007,0.004,0.0,0.0,0.6,0.17320508075688773,0.0,-5.521460917862246,0.007,0.0,0.0,400,330,519,3.258096538021482,64
288,0.14,0.4,0.67,0.007,0.004,0.0,0.0,0.6,0.17320508075688773,0.0,-5.521460917862246,0.007,0.0,0.0,550,268,369,3.5553480614894135,86
291,0.14,0.39,0.64,0.006,0.005,0.0,0.0,0.58,0.17320508075688773,0.0,-5.298317366548036,0.008,0.0,0.0,100,371,505,2.9444389791664403,61
294,0.14,0.39,0.64,0.006,0.005,0.0,0.0,0.58,0.17320508075688773,0.0,-5.298317366548036,0.008,0.0,0.0,400,323,517,3.258096538021482,64
297,0.14,0.39,0.64,0.006,0.005,0.0,0.0,0.58,0.17320508075688773,0.0,-5.298317366548036,0.008,0.0,0.0,550,261,365,3.4965075614664802,84
300,0.28,0.3,0.7,0.022,0.011,0.14,0.07,0.02,0.469041575982343,0.0,-5.521460917862246,0.0097,0.0,0.0,100,284,484,3.367295829986474,58
303,0.28,0.3,0.7,0.022,0.011,0.14,0.07,0.02,0.469041575982343,0.0,-5.521460917862246,0.0097,0.0,0.0,350,214,475,3.332204510175204,54
306,0.28,0.3,0.7,0.022,0.011,0.14,0.07,0.02,0.469041575982343,0.0,-5.521460917862246,0.0097,0.0,0.0,500,165,314,3.6635616461296463,69
309,0.2,0.22,0.68,0.024,0.009,0.15,0.11,0.03,0.47958315233127197,0.0,-4.605170185988091,0.0077,0.0,0.0,100,258,449,3.4657359027997265,65
312,0.2,0.22,0.68,0.024,0.009,0.15,0.11,0.03,0.47958315233127197,0.0,-4.605170185988091,0.0077,0.0,0.0,350,194,454,3.4339872044851463,58
315,0.2,0.22,0.68,0.024,0.009,0.15,0.11,0.03,0.47958315233127197,0.0,-4.605170185988091,0.0077,0.0,0.0,500,152,306,3.784189633918261,80
318,0.34,0.22,0.7,0.016,0.012,0.14,0.1,0.03,0.4472135954999579,0.0,-6.214608098422191,0.0107,0.0,0.0,100,266,454,3.4339872044851463,61
321,0.34,0.22,0.7,0.016,0.012,0.14,0.1,0.03,0.4472135954999579,0.0,-6.214608098422191,0.0107,0.0,0.0,350,198,460,3.4011973816621555,55
324,0.34,0.22,0.7,0.016,0.012,0.14,0.1,0.03,0.4472135954999579,0.0,-6.214608098422191,0.0107,0.0,0.0,500,163,310,3.5263605246161616,70
327,0.28,0.19,0.8,0.01,0.012,0.0,0.06,0.22,0.2,0.0,-4.135166556742356,0.0073,0.0,0.0,100,258,445,3.367295829986474,55
330,0.28,0.19,0.8,0.01,0.012,0.0,0.06,0.22,0.2,0.0,-4.135166556742356,0.0073,0.0,0.0,350,179,457,3.4011973816621555,60
333,0.28,0.19,0.8,0.01,0.012,0.0,0.06,0.22,0.2,0.0,-4.135166556742356,0.0073,0.0,0.0,500,168,338,3.4657359027997265,77
336,0.29,0.2,0.93,0.014,0.015,0.03,0.03,0.36,0.2449489742783178,0.0,-4.017383521085972,0.0045,0.0,0.0,100,300,498,3.295836866004329,54
339,0.29,0.2,0.93,0.014,0.015,0.03,0.03,0.36,0.2449489742783178,0.0,-4.017383521085972,0.0045,0.0,0.0,350,221,514,3.258096538021482,53
342,0.29,0.2,0.93,0.014,0.015,0.03,0.03,0.36,0.2449489742783178,0.0,-4.017383521085972,0.0045,0.0,0.0,500,213,380,3.332204510175204,73
345,0.29,0.22,1.0,0.016,0.011,0.05,0.07,0.34,0.22360679774997896,0.0,-4.509860006183766,0.0035,0.0,0.0,100,270,487,3.332204510175204,51
348,0.29,0.22,1.0,0.016,0.011,0.05,0.07,0.34,0.22360679774997896,0.0,-4.509860006183766,0.0035,0.0,0.0,350,214,503,3.367295829986474,60
351,0.29,0.22,1.0,0.016,0.011,0.05,0.07,0.34,0.22360679774997896,0.0,-4.509860006183766,0.0035,0.0,0.0,500,202,381,3.6109179126442243,77
354,0.22,0.22,0.82,0.015,0.006,0.05,0.06,0.18,0.282842712474619,0.0,-5.298317366548036,0.0082,0.0,0.0,100,289,443,3.332204510175204,63
357,0.22,0.22,0.82,0.015,0.006,0.05,0.06,0.18,0.282842712474619,0.0,-5.298317366548036,0.0082,0.0,0.0,350,207,464,3.2188758248682006,63
360,0.22,0.22,0.82,0.015,0.006,0.05,0.06,0.18,0.282842712474619,0.0,-5.298317366548036,0.0082,0.0,0.0,500,186,330,3.6109179126442243,79
363,0.26,0.23,0.74,0.016,0.006,0.05,0.04,0.15,0.2645751311064591,0.0,-4.961845129926823,0.0108,0.0,0.0,100,262,471,3.1780538303479458,55
366,0.26,0.23,0.74,0.016,0.006,0.05,0.04,0.15,0.2645751311064591,0.0,-4.961845129926823,0.0108,0.0,0.0,350,205,526,3.258096538021482,53
369,0.26,0.23,0.74,0.016,0.006,0.05,0.04,0.15,0.2645751311064591,0.0,-4.961845129926823,0.0108,0.0,0.0,500,179,345,3.5553480614894135,72
372,0.28,0.2,0.72,0.015,0.012,0.32,1.02,1.12,0.4472135954999579,0.27,-6.214608098422191,0.0075,0.0,0.0,100,621,754,2.772588722239781,57
375,0.28,0.2,0.72,0.015,0.012,0.32,1.02,1.12,0.4472135954999579,0.27,-6.214608098422191,0.0075,0.0,0.0,400,538,678,2.772588722239781,55
378,0.28,0.2,0.72,0.015,0.012,0.32,1.02,1.12,0.4472135954999579,0.27,-6.214608098422191,0.0075,0.0,0.0,550,469,504,2.9444389791664403,80
381,0.28,0.18,0.75,0.012,0.009,0.32,1.0,1.25,0.37416573867739417,0.27,-6.214608098422191,0.009,0.0,0.0,27,665,810,2.8903717578961645,63
384,0.28,0.18,0.75,0.012,0.009,0.32,1.0,1.25,0.37416573867739417,0.27,-6.214608098422191,0.009,0.0,0.0,300,566,724,2.6390573296152584,52
387,0.28,0.18,0.75,0.012,0.009,0.32,1.0,1.25,0.37416573867739417,0.27,-6.214608098422191,0.009,0.0,0.0,500,509,573,2.772588722239781,68
390,0.28,0.18,0.75,0.012,0.009,0.32,1.0,1.25,0.37416573867739417,0.27,-6.214608098422191,0.009,0.0,0.0,650,254,364,3.5553480614894135,92
393,0.29,0.2,0.75,0.01,0.009,0.34,1.0,1.25,0.37416573867739417,0.26,-6.214608098422191,0.0075,0.0,0.0,200,624,750,2.772588722239781,57
396,0.29,0.2,0.75,0.01,0.009,0.34,1.0,1.25,0.37416573867739417,0.26,-6.214608098422191,0.0075,0.0,0.0,450,544,644,2.772588722239781,62
399,0.29,0.2,0.75,0.01,0.009,0.34,1.0,1.25,0.37416573867739417,0.26,-6.214608098422191,0.0075,0.0,0.0,600,360,459,3.2188758248682006,87
402,0.3,0.28,0.72,0.014,0.006,0.35,0.93,1.22,0.4,0.21,-6.214608098422191,0.0093,0.0,0.0,100,613,751,2.772588722239781,56
405,0.3,0.28,0.72,0.014,0.006,0.35,0.93,1.22,0.4,0.21,-6.214608098422191,0.0093,0.0,0.0,400,538,690,2.6390573296152584,50
408,0.3,0.28,0.72,0.014,0.006,0.35,0.93,1.22,0.4,0.21,-6.214608098422191,0.0093,0.0,0.0,550,432,510,2.9444389791664403,77
411,0.3,0.26,0.79,0.016,0.015,0.32,1.03,1.13,0.43588989435406733,0.23,-6.214608098422191,0.0085,0.0,0.0,27,620,790,2.8903717578961645,57
414,0.3,0.26,0.79,0.016,0.015,0.32,1.03,1.13,0.43588989435406733,0.23,-6.214608098422191,0.0085,0.0,0.0,300,562,710,2.5649493574615367,42
417,0.3,0.26,0.79,0.016,0.015,0.32,1.03,1.13,0.43588989435406733,0.23,-6.214608098422191,0.0085,0.0,0.0,500,470,562,2.833213344056216,64
420,0.3,0.26,0.79,0.016,0.015,0.32,1.03,1.13,0.43588989435406733,0.23,-6.214608098422191,0.0085,0.0,0.0,650,250,367,3.295836866004329,90
423,0.29,0.26,0.76,0.009,0.007,0.45,1.12,1.18,0.2645751311064591,0.23,-5.809142990314028,0.0103,0.0,0.0,200,618,752,2.70805020110221,54
426,0.29,0.26,0.76,0.009,0.007,0.45,1.12,1.18,0.2645751311064591,0.23,-5.809142990314028,0.0103,0.0,0.0,450,545,647,2.70805020110221,67
429,0.29,0.26,0.76,0.009,0.007,0.45,1.12,1.18,0.2645751311064591,0.23,-5.809142990314028,0.0103,0.0,0.0,600,378,470,3.091042453358316,88
432,0.29,0.26,0.77,0.009,0.007,0.46,1.12,1.2,0.282842712474619,0.23,-5.521460917862246,0.0095,0.0,0.0,100,622,775,2.772588722239781,61
435,0.29,0.26,0.77,0.009,0.007,0.46,1.12,1.2,0.282842712474619,0.23,-5.521460917862246,0.0095,0.0,0.0,400,560,687,2.5649493574615367,52
438,0.29,0.26,0.77,0.009,0.007,0.46,1.12,1.2,0.282842712474619,0.23,-5.521460917862246,0.0095,0.0,0.0,550,446,525,2.9444389791664403,80
441,0.29,0.21,0.66,0.01,0.008,0.51,1.07,1.29,0.2449489742783178,0.23,-5.298317366548036,0.0097,0.0,0.0,27,640,800,2.8903717578961645,62
444,0.29,0.21,0.66,0.01,0.008,0.51,1.07,1.29,0.2449489742783178,0.23,-5.298317366548036,0.0097,0.0,0.0,300,560,716,2.6390573296152584,55
447,0.29,0.21,0.66,0.01,0.008,0.51,1.07,1.29,0.2449489742783178,0.23,-5.298317366548036,0.0097,0.0,0.0,500,493,558,2.9444389791664403,75
450,0.29,0.21,0.66,0.01,0.008,0.51,1.07,1.29,0.2449489742783178,0.23,-5.298317366548036,0.0097,0.0,0.0,650,267,370,3.4657359027997265,91
453,0.3,0.27,0.7,0.012,0.012,0.44,1.1,1.35,0.33166247903553997,0.27,-5.809142990314028,0.0082,0.0,0.0,200,598,747,2.772588722239781,59
456,0.3,0.27,0.7,0.012,0.012,0.44,1.1,1.35,0.33166247903553997,0.27,-5.809142990314028,0.0082,0.0,0.0,450,522,631,2.833213344056216,68
459,0.3,0.27,0.7,0.012,0.012,0.44,1.1,1.35,0.33166247903553997,0.27,-5.809142990314028,0.0082,0.0,0.0,600,358,451,3.295836866004329,89
462,0.18,0.26,1.33,0.015,0.008,0.55,0.11,0.49,0.33166247903553997,0.0,-3.575550768806933,0.006,0.0,0.0,100,393,525,3.1354942159291497,69
465,0.18,0.26,1.33,0.015,0.008,0.55,0.11,0.49,0.33166247903553997,0.0,-3.575550768806933,0.006,0.0,0.0,350,399,575,3.258096538021482,70
468,0.18,0.26,1.33,0.015,0.008,0.55,0.11,0.49,0.33166247903553997,0.0,-3.575550768806933,0.006,0.0,0.0,500,322,409,3.1354942159291497,78
471,0.17,0.23,1.34,0.014,0.009,0.57,0.16,0.49,0.33166247903553997,0.0,-3.270169119255751,0.007,0.0,0.0,27,455,590,3.258096538021482,72
474,0.17,0.23,1.34,0.014,0.009,0.57,0.16,0.49,0.33166247903553997,0.0,-3.270169119255751,0.007,0.0,0.0,300,435,608,2.995732273553991,61
477,0.17,0.23,1.34,0.014,0.009,0.57,0.16,0.49,0.33166247903553997,0.0,-3.270169119255751,0.007,0.0,0.0,450,367,505,3.2188758248682006,75
480,0.17,0.23,1.34,0.014,0.009,0.57,0.16,0.49,0.33166247903553997,0.0,-3.270169119255751,0.007,0.0,0.0,600,248,308,3.6109179126442243,85
483,0.17,0.33,1.37,0.016,0.014,0.6,0.08,0.53,0.4898979485566356,0.0,-4.8283137373023015,0.0071,0.0,0.0,200,404,548,2.995732273553991,66
486,0.17,0.33,1.37,0.016,0.014,0.6,0.08,0.53,0.4898979485566356,0.0,-4.8283137373023015,0.0071,0.0,0.0,400,378,532,2.9444389791664403,45
489,0.17,0.33,1.37,0.016,0.014,0.6,0.08,0.53,0.4898979485566356,0.0,-4.8283137373023015,0.0071,0.0,0.0,550,304,369,3.295836866004329,82
492,0.17,0.35,1.44,0.015,0.01,0.58,0.08,0.5,0.47958315233127197,0.0,-5.115995809754082,0.0079,0.0,0.0,27,420,580,3.295836866004329,71
495,0.17,0.35,1.44,0.015,0.01,0.58,0.08,0.5,0.47958315233127197,0.0,-5.115995809754082,0.0079,0.0,0.0,300,381,556,2.995732273553991,60
498,0.17,0.35,1.44,0.015,0.01,0.58,0.08,0.5,0.47958315233127197,0.0,-5.115995809754082,0.0079,0.0,0.0,450,336,462,3.091042453358316,66
501,0.17,0.35,1.44,0.015,0.01,0.58,0.08,0.5,0.47958315233127197,0.0,-5.115995809754082,0.0079,0.0,0.0,600,240,300,3.6635616461296463,88
504,0.19,0.33,1.41,0.014,0.006,0.58,0.1,0.53,0.5,0.0,-4.8283137373023015,0.0077,0.0,0.0,200,395,540,3.1354942159291497,69
507,0.19,0.33,1.41,0.014,0.006,0.58,0.1,0.53,0.5,0.0,-4.8283137373023015,0.0077,0.0,0.0,400,363,522,3.1354942159291497,59
510,0.19,0.33,1.41,0.014,0.006,0.58,0.1,0.53,0.5,0.0,-4.8283137373023015,0.0077,0.0,0.0,550,288,356,3.367295829986474,83
513,0.12,0.25,0.48,0.008,0.012,0.04,0.64,0.51,0.2,0.0,-5.115995809754082,0.013,0.0,0.0,100,261,454,3.332204510175204,72
516,0.12,0.25,0.48,0.008,0.012,0.04,0.64,0.51,0.2,0.0,-5.115995809754082,0.013,0.0,0.0,400,237,564,3.258096538021482,66
519,0.12,0.25,0.48,0.008,0.012,0.04,0.64,0.51,0.2,0.0,-5.115995809754082,0.013,0.0,0.0,550,222,434,3.367295829986474,78
522,0.16,0.24,0.49,0.012,0.007,0.035,0.61,0.51,0.2,0.0,-5.115995809754082,0.0086,0.0,0.0,100,260,408,3.367295829986474,67
525,0.16,0.24,0.49,0.012,0.007,0.035,0.61,0.51,0.2,0.0,-5.115995809754082,0.0086,0.0,0.0,400,191,456,3.4011973816621555,76
528,0.16,0.24,0.49,0.012,0.007,0.035,0.61,0.51,0.2,0.0,-5.115995809754082,0.0086,0.0,0.0,550,176,349,3.6109179126442243,87
531,0.12,0.25,0.43,0.006,0.011,0.03,0.59,0.51,0.17320508075688773,0.0,-5.115995809754082,0.015,0.0,0.0,100,301,419,3.4339872044851463,79
534,0.12,0.25,0.43,0.006,0.011,0.03,0.59,0.51,0.17320508075688773,0.0,-5.115995809754082,0.015,0.0,0.0,400,213,455,3.367295829986474,78
537,0.12,0.25,0.43,0.006,0.011,0.03,0.59,0.51,0.17320508075688773,0.0,-5.115995809754082,0.015,0.0,0.0,550,204,353,3.4657359027997265,86
540,0.12,0.25,0.44,0.013,0.012,0.05,0.71,0.52,0.2449489742783178,0.0,-5.521460917862246,0.0058,0.0,0.0,100,276,438,3.258096538021482,66
543,0.12,0.25,0.44,0.013,0.012,0.05,0.71,0.52,0.2449489742783178,0.0,-5.521460917862246,0.0058,0.0,0.0,400,226,530,3.2188758248682006,62
546,0.12,0.25,0.44,0.013,0.012,0.05,0.71,0.52,0.2449489742783178,0.0,-5.521460917862246,0.0058,0.0,0.0,550,220,418,3.295836866004329,76
549,0.12,0.24,0.47,0.008,0.011,0.04,0.71,0.49,0.2449489742783178,0.0,-5.115995809754082,0.013,0.0,0.0,100,255,441,3.367295829986474,76
552,0.12,0.24,0.47,0.008,0.011,0.04,0.71,0.49,0.2449489742783178,0.0,-5.115995809754082,0.013,0.0,0.0,400,246,556,3.258096538021482,64
555,0.12,0.24,0.47,0.008,0.011,0.04,0.71,0.49,0.2449489742783178,0.0,-5.115995809754082,0.013,0.0,0.0,550,224,416,3.295836866004329,81
558,0.15,0.26,0.45,0.012,0.006,0.033,0.58,0.49,0.2,0.0,-5.115995809754082,0.0084,0.0,0.0,100,261,418,3.4657359027997265,65
561,0.15,0.26,0.45,0.012,0.006,0.033,0.58,0.49,0.2,0.0,-5.115995809754082,0.0084,0.0,0.0,400,174,449,3.4657359027997265,76
564,0.15,0.26,0.45,0.012,0.006,0.033,0.58,0.49,0.2,0.0,-5.115995809754082,0.0084,0.0,0.0,550,178,337,3.6109179126442243,88
567,0.14,0.22,0.45,0.013,0.013,0.06,0.68,0.52,0.2449489742783178,0.0,-5.521460917862246,0.0062,0.0,0.0,100,249,435,3.295836866004329,65
570,0.14,0.22,0.45,0.013,0.013,0.06,0.68,0.52,0.2449489742783178,0.0,-5.521460917862246,0.0062,0.0,0.0,400,254,524,3.2188758248682006,60
573,0.14,0.22,0.45,0.013,0.013,0.06,0.68,0.52,0.2449489742783178,0.0,-5.521460917862246,0.0062,0.0,0.0,550,214,413,3.332204510175204,76
576,0.15,0.21,0.42,0.015,0.011,0.06,0.66,0.52,0.2645751311064591,0.0,-5.521460917862246,0.0056,0.0,0.0,100,221,411,3.258096538021482,63
579,0.15,0.21,0.42,0.015,0.011,0.06,0.66,0.52,0.2645751311064591,0.0,-5.521460917862246,0.0056,0.0,0.0,400,213,507,3.295836866004329,60
582,0.15,0.21,0.42,0.015,0.011,0.06,0.66,0.52,0.2645751311064591,0.0,-5.521460917862246,0.0056,0.0,0.0,550,203,395,3.4339872044851463,78
585,0.15,0.25,0.45,0.013,0.008,0.032,0.6,0.48,0.2,0.0,-5.115995809754082,0.0082,0.0,0.0,100,260,415,3.4339872044851463,66
588,0.15,0.25,0.45,0.013,0.008,0.032,0.6,0.48,0.2,0.0,-5.115995809754082,0.0082,0.0,0.0,400,180,452,3.4339872044851463,75
591,0.15,0.25,0.45,0.013,0.008,0.032,0.6,0.48,0.2,0.0,-5.115995809754082,0.0082,0.0,0.0,550,176,338,3.6635616461296463,89
594,0.17,0.39,0.6,0.022,0.02,0.11,1.31,1.02,0.33166247903553997,0.28,-5.521460917862246,0.0078,0.0,0.0,100,532,666,2.833213344056216,50
597,0.17,0.39,0.6,0.022,0.02,0.11,1.31,1.02,0.33166247903553997,0.28,-5.521460917862246,0.0078,0.0,0.0,400,456,605,2.302585092994046,22
600,0.17,0.39,0.6,0.022,0.02,0.11,1.31,1.02,0.33166247903553997,0.28,-5.521460917862246,0.0078,0.0,0.0,550,428,492,2.833213344056216,54
603,0.16,0.47,0.62,0.01,0.01,0.19,1.01,0.92,0.3872983346207417,0.24,-5.809142990314028,0.0111,0.0,0.0,27,535,690,2.833213344056216,61
606,0.16,0.47,0.62,0.01,0.01,0.19,1.01,0.92,0.3872983346207417,0.24,-5.809142990314028,0.0111,0.0,0.0,300,491,626,2.5649493574615367,52
609,0.16,0.47,0.62,0.01,0.01,0.19,1.01,0.92,0.3872983346207417,0.24,-5.809142990314028,0.0111,0.0,0.0,500,436,514,2.833213344056216,66
612,0.16,0.47,0.62,0.01,0.01,0.19,1.01,0.92,0.3872983346207417,0.24,-5.809142990314028,0.0111,0.0,0.0,650,261,339,3.1354942159291497,86
615,0.14,0.34,0.73,0.01,0.009,0.13,1.06,0.96,0.282842712474619,0.23,-5.809142990314028,0.0102,0.0,0.0,200,536,645,2.4849066497880004,36
618,0.14,0.34,0.73,0.01,0.009,0.13,1.06,0.96,0.282842712474619,0.23,-5.809142990314028,0.0102,0.0,0.0,450,462,554,2.772588722239781,55
621,0.14,0.34,0.73,0.01,0.009,0.13,1.06,0.96,0.282842712474619,0.23,-5.809142990314028,0.0102,0.0,0.0,600,345,397,3.332204510175204,81
624,0.18,0.37,0.66,0.018,0.017,0.1,1.07,1.03,0.34641016151377546,0.3,-3.912023005428146,0.0081,0.0,0.0,100,584,716,2.5649493574615367,47
628,0.18,0.37,0.66,0.018,0.017,0.1,1.07,1.03,0.34641016151377546,0.3,-3.912023005428146,0.0081,0.0,0.0,450,471,592,2.70805020110221,44
631,0.18,0.37,0.66,0.018,0.017,0.1,1.07,1.03,0.34641016151377546,0.3,-3.912023005428146,0.0081,0.0,0.0,600,359,416,2.9444389791664403,77
634,0.16,0.47,0.62,0.01,0.01,0.19,1.0,0.92,0.3872983346207417,0.24,-6.214608098422191,0.0104,0.0,0.0,100,508,644,2.833213344056216,62
637,0.16,0.47,0.62,0.01,0.01,0.19,1.0,0.92,0.3872983346207417,0.24,-6.214608098422191,0.0104,0.0,0.0,400,440,580,2.70805020110221,53
640,0.16,0.47,0.62,0.01,0.01,0.19,1.0,0.92,0.3872983346207417,0.24,-6.214608098422191,0.0104,0.0,0.0,550,384,450,2.70805020110221,62
643,0.18,0.37,0.61,0.019,0.018,0.11,1.09,1.12,0.2645751311064591,0.28,-4.135166556742356,0.0064,0.0,0.0,27,650,790,2.772588722239781,49
646,0.18,0.37,0.61,0.019,0.018,0.11,1.09,1.12,0.2645751311064591,0.28,-4.135166556742356,0.0064,0.0,0.0,300,199,660,2.4849066497880004,45
649,0.18,0.37,0.61,0.019,0.018,0.11,1.09,1.12,0.2645751311064591,0.28,-4.135166556742356,0.0064,0.0,0.0,500,440,540,2.5649493574615367,51
652,0.18,0.37,0.61,0.019,0.018,0.11,1.09,1.12,0.2645751311064591,0.28,-4.135166556742356,0.0064,0.0,0.0,650,318,393,3.044522437723423,78
655,0.16,0.52,0.79,0.01,0.008,0.13,1.16,0.97,0.33166247903553997,0.23,-5.809142990314028,0.0106,0.0,0.0,200,522,638,2.5649493574615367,40
658,0.16,0.52,0.79,0.01,0.008,0.13,1.16,0.97,0.33166247903553997,0.23,-5.809142990314028,0.0106,0.0,0.0,450,463,580,2.9444389791664403,67
661,0.16,0.52,0.79,0.01,0.008,0.13,1.16,0.97,0.33166247903553997,0.23,-5.809142990314028,0.0106,0.0,0.0,600,338,405,3.258096538021482,84
664,0.18,0.39,0.63,0.012,0.012,0.23,1.22,0.89,0.41231056256176607,0.23,-6.214608098422191,0.0103,0.0,0.0,100,499,635,2.8903717578961645,64
667,0.18,0.39,0.63,0.012,0.012,0.23,1.22,0.89,0.41231056256176607,0.23,-6.214608098422191,0.0103,0.0,0.0,400,473,587,2.6390573296152584,51
670,0.18,0.39,0.63,0.012,0.012,0.23,1.22,0.89,0.41231056256176607,0.23,-6.214608098422191,0.0103,0.0,0.0,550,380,446,2.8903717578961645,74
673,0.15,0.52,0.78,0.01,0.009,0.12,1.17,0.98,0.282842712474619,0.23,-5.809142990314028,0.0106,0.0,0.0,27,555,680,2.995732273553991,69
676,0.15,0.52,0.78,0.01,0.009,0.12,1.17,0.98,0.282842712474619,0.23,-5.809142990314028,0.0106,0.0,0.0,300,496,607,2.772588722239781,66
679,0.15,0.52,0.78,0.01,0.009,0.12,1.17,0.98,0.282842712474619,0.23,-5.809142990314028,0.0106,0.0,0.0,500,433,505,2.9444389791664403,75
682,0.15,0.52,0.78,0.01,0.009,0.12,1.17,0.98,0.282842712474619,0.23,-5.809142990314028,0.0106,0.0,0.0,650,252,333,3.1354942159291497,88
685,0.15,0.3,1.14,0.009,0.021,0.31,0.2,0.08,0.37416573867739417,0.0,-3.575550768806933,0.0082,0.42,0.0,200,439,557,3.044522437723423,70
688,0.15,0.3,1.14,0.009,0.021,0.31,0.2,0.08,0.37416573867739417,0.0,-3.575550768806933,0.0082,0.42,0.0,400,410,513,3.367295829986474,74
691,0.15,0.3,1.14,0.009,0.021,0.31,0.2,0.08,0.37416573867739417,0.0,-3.575550768806933,0.0082,0.42,0.0,550,271,344,3.367295829986474,74
694,0.15,0.28,1.32,0.019,0.005,0.077,0.053,0.008,0.282842712474619,0.07,-4.074541934925921,0.0066,0.401,0.0,100,513,645,2.8903717578961645,60
697,0.15,0.28,1.32,0.019,0.005,0.077,0.053,0.008,0.282842712474619,0.07,-4.074541934925921,0.0066,0.401,0.0,350,436,614,3.1780538303479458,67
700,0.15,0.28,1.32,0.019,0.005,0.077,0.053,0.008,0.282842712474619,0.07,-4.074541934925921,0.0066,0.401,0.0,500,303,410,3.1780538303479458,79
703,0.16,0.28,1.14,0.017,0.016,0.33,0.24,0.08,0.36055512754639896,0.0,-4.199705077879927,0.0067,0.437,0.0,27,590,692,3.044522437723423,68
706,0.16,0.28,1.14,0.017,0.016,0.33,0.24,0.08,0.36055512754639896,0.0,-4.199705077879927,0.0067,0.437,0.0,300,566,701,3.044522437723423,61
709,0.16,0.28,1.14,0.017,0.016,0.33,0.24,0.08,0.36055512754639896,0.0,-4.199705077879927,0.0067,0.437,0.0,450,467,543,2.995732273553991,76
712,0.16,0.28,1.14,0.017,0.016,0.33,0.24,0.08,0.36055512754639896,0.0,-4.199705077879927,0.0067,0.437,0.0,600,186,316,3.4339872044851463,45
715,0.16,0.48,1.21,0.017,0.009,0.02,0.02,0.1,0.1414213562373095,0.05,-3.2188758248682006,0.0028,0.414,0.0,200,513,641,2.9444389791664403,70
718,0.16,0.48,1.21,0.017,0.009,0.02,0.02,0.1,0.1414213562373095,0.05,-3.2188758248682006,0.0028,0.414,0.0,400,431,567,3.1780538303479458,82
721,0.16,0.48,1.21,0.017,0.009,0.02,0.02,0.1,0.1414213562373095,0.05,-3.2188758248682006,0.0028,0.414,0.0,550,326,412,3.2188758248682006,88
724,0.13,0.33,1.23,0.014,0.015,0.44,0.04,0.076,0.2,0.04,-3.4420193761824103,0.0074,0.389,0.0,100,500,592,3.044522437723423,70
727,0.13,0.33,1.23,0.014,0.015,0.44,0.04,0.076,0.2,0.04,-3.4420193761824103,0.0074,0.389,0.0,350,446,595,3.258096538021482,72
730,0.13,0.33,1.23,0.014,0.015,0.44,0.04,0.076,0.2,0.04,-3.4420193761824103,0.0074,0.389,0.0,500,368,430,3.367295829986474,85
733,0.14,0.3,1.09,0.008,0.015,0.39,0.12,0.09,0.41231056256176607,0.0,-3.4420193761824103,0.0098,0.39,0.0,27,451,578,3.2188758248682006,71
736,0.14,0.3,1.09,0.008,0.015,0.39,0.12,0.09,0.41231056256176607,0.0,-3.4420193761824103,0.0098,0.39,0.0,300,396,571,3.1780538303479458,62
739,0.14,0.3,1.09,0.008,0.015,0.39,0.12,0.09,0.41231056256176607,0.0,-3.4420193761824103,0.0098,0.39,0.0,450,342,432,3.295836866004329,73
742,0.14,0.3,1.09,0.008,0.015,0.39,0.12,0.09,0.41231056256176607,0.0,-3.4420193761824103,0.0098,0.39,0.0,600,189,269,3.6635616461296463,74
745,0.14,0.21,1.29,0.016,0.008,0.21,0.02,0.06,0.3,0.03,-3.863232841258714,0.0065,0.39,0.0,200,443,578,2.9444389791664403,66
748,0.14,0.21,1.29,0.016,0.008,0.21,0.02,0.06,0.3,0.03,-3.863232841258714,0.0065,0.39,0.0,400,422,548,3.2188758248682006,71
751,0.14,0.21,1.29,0.016,0.008,0.21,0.02,0.06,0.3,0.03,-3.863232841258714,0.0065,0.39,0.0,550,299,374,3.4339872044851463,80
754,0.148,0.49,1.27,0.03,0.005,0.04,0.19,0.02,0.17320508075688773,0.07,-3.3242363405260273,0.0065,0.429,0.0,100,497,593,3.091042453358316,77
757,0.148,0.49,1.27,0.03,0.005,0.04,0.19,0.02,0.17320508075688773,0.07,-3.3242363405260273,0.0065,0.429,0.0,350,459,602,3.258096538021482,76
760,0.148,0.49,1.27,0.03,0.005,0.04,0.19,0.02,0.17320508075688773,0.07,-3.3242363405260273,0.0065,0.429,0.0,500,328,409,3.5263605246161616,90
763,0.17,0.52,1.27,0.017,0.015,0.02,0.02,0.1,0.1414213562373095,0.05,-3.0159349808715104,0.0026,0.436,0.0,27,623,736,2.9444389791664403,70
766,0.17,0.52,1.27,0.017,0.015,0.02,0.02,0.1,0.1414213562373095,0.05,-3.0159349808715104,0.0026,0.436,0.0,300,573,711,2.9444389791664403,69
769,0.17,0.52,1.27,0.017,0.015,0.02,0.02,0.1,0.1414213562373095,0.05,-3.0159349808715104,0.0026,0.436,0.0,450,483,576,2.9444389791664403,81
772,0.17,0.52,1.27,0.017,0.015,0.02,0.02,0.1,0.1414213562373095,0.05,-3.0159349808715104,0.0026,0.436,0.0,600,247,366,3.295836866004329,85
775,0.12,0.33,1.37,0.016,0.012,0.19,0.03,0.01,0.17320508075688773,0.08,-3.170085660698769,0.007,0.381,0.0,200,507,630,2.9444389791664403,68
778,0.12,0.33,1.37,0.016,0.012,0.19,0.03,0.01,0.17320508075688773,0.08,-3.170085660698769,0.007,0.381,0.0,400,450,580,3.258096538021482,77
781,0.12,0.33,1.37,0.016,0.012,0.19,0.03,0.01,0.17320508075688773,0.08,-3.170085660698769,0.007,0.381,0.0,550,281,382,3.4011973816621555,82
784,0.13,0.34,1.23,0.012,0.016,0.46,0.03,0.072,0.1414213562373095,0.042,-3.3524072174927233,0.0065,0.387,0.0,100,510,612,2.9444389791664403,69
787,0.13,0.34,1.23,0.012,0.016,0.46,0.03,0.072,0.1414213562373095,0.042,-3.3524072174927233,0.0065,0.387,0.0,350,437,609,3.295836866004329,76
790,0.13,0.34,1.23,0.012,0.016,0.46,0.03,0.072,0.1414213562373095,0.042,-3.3524072174927233,0.0065,0.387,0.0,500,359,436,3.367295829986474,86
793,0.12,0.37,1.32,0.012,0.012,0.22,0.03,0.07,0.2645751311064591,0.04,-3.506557897319982,0.0064,0.387,0.0,27,455,571,3.332204510175204,75
796,0.12,0.37,1.32,0.012,0.012,0.22,0.03,0.07,0.2645751311064591,0.04,-3.506557897319982,0.0064,0.387,0.0,300,372,571,3.2188758248682006,68
799,0.12,0.37,1.32,0.012,0.012,0.22,0.03,0.07,0.2645751311064591,0.04,-3.506557897319982,0.0064,0.387,0.0,450,321,450,3.4657359027997265,78
802,0.12,0.37,1.32,0.012,0.012,0.22,0.03,0.07,0.2645751311064591,0.04,-3.506557897319982,0.0064,0.387,0.0,600,185,258,3.9318256327243257,82
805,0.16,0.29,1.42,0.013,0.006,0.041,0.054,0.011,0.282842712474619,0.079,-5.115995809754082,0.0048,0.429,0.0,200,482,636,2.995732273553991,70
808,0.16,0.29,1.42,0.013,0.006,0.041,0.054,0.011,0.282842712474619,0.079,-5.115995809754082,0.0048,0.429,0.0,400,422,551,3.1780538303479458,78
811,0.16,0.29,1.42,0.013,0.006,0.041,0.054,0.011,0.282842712474619,0.079,-5.115995809754082,0.0048,0.429,0.0,550,251,343,3.295836866004329,89
814,0.123,0.44,1.19,0.021,0.006,0.05,0.2,0.02,0.17320508075688773,0.07,-3.2188758248682006,0.006,0.39,0.0,100,486,578,3.091042453358316,77
817,0.123,0.44,1.19,0.021,0.006,0.05,0.2,0.02,0.17320508075688773,0.07,-3.2188758248682006,0.006,0.39,0.0,350,451,598,3.367295829986474,81
820,0.123,0.44,1.19,0.021,0.006,0.05,0.2,0.02,0.17320508075688773,0.07,-3.2188758248682006,0.006,0.39,0.0,500,338,424,3.4339872044851463,90
823,0.14,0.38,1.24,0.014,0.014,0.43,0.03,0.084,0.22360679774997896,0.043,-3.2188758248682006,0.0066,0.403,0.0,27,539,648,3.1780538303479458,72
826,0.14,0.38,1.24,0.014,0.014,0.43,0.03,0.084,0.22360679774997896,0.043,-3.2188758248682006,0.0066,0.403,0.0,300,471,637,3.044522437723423,68
829,0.14,0.38,1.24,0.014,0.014,0.43,0.03,0.084,0.22360679774997896,0.043,-3.2188758248682006,0.0066,0.403,0.0,450,403,503,3.1354942159291497,79
832,0.14,0.38,1.24,0.014,0.014,0.43,0.03,0.084,0.22360679774997896,0.043,-3.2188758248682006,0.0066,0.403,0.0,600,229,313,3.6635616461296463,83
835,0.14,0.33,1.45,0.025,0.012,0.18,0.03,0.01,0.1414213562373095,0.06,-2.995732273553991,0.0051,0.412,0.0,200,500,616,2.995732273553991,65
838,0.14,0.33,1.45,0.025,0.012,0.18,0.03,0.01,0.1414213562373095,0.06,-2.995732273553991,0.0051,0.412,0.0,400,437,570,3.258096538021482,76
841,0.14,0.33,1.45,0.025,0.012,0.18,0.03,0.01,0.1414213562373095,0.06,-2.995732273553991,0.0051,0.412,0.0,550,278,367,3.58351893845611,89
844,0.15,0.25,1.38,0.014,0.006,0.04,0.041,0.006,0.282842712474619,0.088,-4.199705077879927,0.0076,0.407,0.0,100,468,586,3.1780538303479458,71
847,0.15,0.25,1.38,0.014,0.006,0.04,0.041,0.006,0.282842712474619,0.088,-4.199705077879927,0.0076,0.407,0.0,350,395,573,3.1780538303479458,68
850,0.15,0.25,1.38,0.014,0.006,0.04,0.041,0.006,0.282842712474619,0.088,-4.199705077879927,0.0076,0.407,0.0,500,265,378,3.6635616461296463,79
853,0.143,0.5,1.2,0.03,0.007,0.06,0.17,0.02,0.1414213562373095,0.07,-3.540459448995663,0.0068,0.409,0.0,27,488,601,3.295836866004329,77
856,0.143,0.5,1.2,0.03,0.007,0.06,0.17,0.02,0.1414213562373095,0.07,-3.540459448995663,0.0068,0.409,0.0,300,425,604,3.2188758248682006,74
859,0.143,0.5,1.2,0.03,0.007,0.06,0.17,0.02,0.1414213562373095,0.07,-3.540459448995663,0.0068,0.409,0.0,450,356,468,3.4657359027997265,84
862,0.143,0.5,1.2,0.03,0.007,0.06,0.17,0.02,0.1414213562373095,0.07,-3.540459448995663,0.0068,0.409,0.0,600,193,279,3.9889840465642745,91
865,0.17,0.49,1.26,0.013,0.01,0.01,0.02,0.09,0.1414213562373095,0.04,-3.101092789211817,0.0025,0.429,0.0,200,532,666,2.8903717578961645,68
868,0.17,0.49,1.26,0.013,0.01,0.01,0.02,0.09,0.1414213562373095,0.04,-3.101092789211817,0.0025,0.429,0.0,400,413,566,3.332204510175204,83
871,0.17,0.49,1.26,0.013,0.01,0.01,0.02,0.09,0.1414213562373095,0.04,-3.101092789211817,0.0025,0.429,0.0,550,335,415,3.1780538303479458,87
874,0.13,0.42,1.28,0.014,0.012,0.21,0.22,0.05,0.2,0.03,-3.2968373663379125,0.0072,0.424,0.0,100,451,567,3.1780538303479458,76
877,0.13,0.42,1.28,0.014,0.012,0.21,0.22,0.05,0.2,0.03,-3.2968373663379125,0.0072,0.424,0.0,350,391,580,3.367295829986474,75
880,0.13,0.42,1.28,0.014,0.012,0.21,0.22,0.05,0.2,0.03,-3.2968373663379125,0.0072,0.424,0.0,500,325,405,3.4657359027997265,85
883,0.16,0.41,1.48,0.014,0.01,0.02,0.02,0.01,0.17320508075688773,0.08,-3.4112477175156566,0.0079,0.436,0.0,27,577,693,2.995732273553991,62
886,0.16,0.41,1.48,0.014,0.01,0.02,0.02,0.01,0.17320508075688773,0.08,-3.4112477175156566,0.0079,0.436,0.0,300,483,664,2.8903717578961645,59
889,0.16,0.41,1.48,0.014,0.01,0.02,0.02,0.01,0.17320508075688773,0.08,-3.4112477175156566,0.0079,0.436,0.0,450,404,513,3.2188758248682006,78
892,0.16,0.41,1.48,0.014,0.01,0.02,0.02,0.01,0.17320508075688773,0.08,-3.4112477175156566,0.0079,0.436,0.0,600,198,313,3.4011973816621555,77
895,0.23,0.23,1.23,0.027,0.012,0.03,0.04,0.017,0.1,0.009,-5.809142990314028,0.0111,0.0,0.0017,150,367,651,2.772588722239781,51
898,0.23,0.23,1.23,0.027,0.012,0.03,0.04,0.017,0.1,0.009,-5.809142990314028,0.0111,0.0,0.0017,300,290,677,3.295836866004329,59
901,0.23,0.23,1.23,0.027,0.012,0.03,0.04,0.017,0.1,0.009,-5.809142990314028,0.0111,0.0,0.0017,450,240,498,3.4011973816621555,72
904,0.22,0.22,1.24,0.021,0.008,0.03,0.05,0.017,0.1,0.005,-5.298317366548036,0.0116,0.0,0.0017,27,382,580,3.332204510175204,70
907,0.22,0.22,1.24,0.021,0.008,0.03,0.05,0.017,0.1,0.005,-5.298317366548036,0.0116,0.0,0.0017,200,396,705,2.772588722239781,47
910,0.22,0.22,1.24,0.021,0.008,0.03,0.05,0.017,0.1,0.005,-5.298317366548036,0.0116,0.0,0.0017,350,268,632,3.332204510175204,65
913,0.22,0.22,1.24,0.021,0.008,0.03,0.05,0.017,0.1,0.005,-5.298317366548036,0.0116,0.0,0.0017,500,209,428,3.4011973816621555,78
914,0.22,0.22,1.24,0.021,0.008,0.03,0.05,0.017,0.1,0.005,-5.298317366548036,0.0116,0.0,0.0017,550,200,328,3.6888794541139363,86