File: data_clean.csv
, C, Si, Mn, P, S, Ni, Cr, Mo, Cu,V, Al, N,Ceq,Nb + Ta, Temperature (Â°C), 0.2% Proof Stress (MPa), Tensile Strength (MPa), Elongation (%), Reduction in Area (%)
0,0.12,0.36,0.52,0.009,0.003,0.089,0.97,0.61,0.04,0.0,0.003,0.0066,0.0,0.0,27,342,490,30,71
2,0.12,0.36,0.52,0.009,0.003,0.089,0.97,0.61,0.04,0.0,0.003,0.0066,0.0,0.0,200,337,465,23,69
4,0.12,0.36,0.52,0.009,0.003,0.089,0.97,0.61,0.04,0.0,0.003,0.0066,0.0,0.0,400,316,489,26,79
6,0.12,0.36,0.52,0.009,0.003,0.089,0.97,0.61,0.04,0.0,0.003,0.0066,0.0,0.0,500,274,431,28,85
8,0.12,0.36,0.52,0.009,0.003,0.089,0.97,0.61,0.04,0.0,0.003,0.0066,0.0,0.0,600,220,314,42,88
10,0.09,0.37,0.49,0.006,0.005,0.055,0.98,0.57,0.07,0.0,0.005,0.008,0.0,0.0,27,310,463,34,76
12,0.09,0.37,0.49,0.006,0.005,0.055,0.98,0.57,0.07,0.0,0.005,0.008,0.0,0.0,200,296,439,25,77
14,0.09,0.37,0.49,0.006,0.005,0.055,0.98,0.57,0.07,0.0,0.005,0.008,0.0,0.0,400,257,472,28,78
16,0.09,0.37,0.49,0.006,0.005,0.055,0.98,0.57,0.07,0.0,0.005,0.008,0.0,0.0,500,232,423,28,84
18,0.09,0.37,0.49,0.006,0.005,0.055,0.98,0.57,0.07,0.0,0.005,0.008,0.0,0.0,600,176,297,44,89
20,0.1,0.28,0.49,0.008,0.009,0.028,0.9,0.56,0.08,0.0,0.006,0.009,0.0,0.0,27,306,463,32,78
22,0.1,0.28,0.49,0.008,0.009,0.028,0.9,0.56,0.08,0.0,0.006,0.009,0.0,0.0,200,303,459,22,73
24,0.1,0.28,0.49,0.008,0.009,0.028,0.9,0.56,0.08,0.0,0.006,0.009,0.0,0.0,400,264,464,25,75
26,0.1,0.28,0.49,0.008,0.009,0.028,0.9,0.56,0.08,0.0,0.006,0.009,0.0,0.0,500,237,424,24,81
28,0.1,0.28,0.49,0.008,0.009,0.028,0.9,0.56,0.08,0.0,0.006,0.009,0.0,0.0,600,212,297,37,88
30,0.12,0.43,0.48,0.014,0.008,0.051,0.96,0.56,0.08,0.0,0.006,0.008,0.0,0.0,27,343,502,32,76
32,0.12,0.43,0.48,0.014,0.008,0.051,0.96,0.56,0.08,0.0,0.006,0.008,0.0,0.0,200,329,482,23,73
34,0.12,0.43,0.48,0.014,0.008,0.051,0.96,0.56,0.08,0.0,0.006,0.008,0.0,0.0,400,249,493,27,76
36,0.12,0.43,0.48,0.014,0.008,0.051,0.96,0.56,0.08,0.0,0.006,0.008,0.0,0.0,500,255,434,24,81
38,0.12,0.43,0.48,0.014,0.008,0.051,0.96,0.56,0.08,0.0,0.006,0.008,0.0,0.0,600,202,301,36,89
40,0.12,0.28,0.44,0.018,0.008,0.03,0.99,0.54,0.08,0.0,0.007,0.01,0.0,0.0,27,339,493,33,77
42,0.12,0.28,0.44,0.018,0.008,0.03,0.99,0.54,0.08,0.0,0.007,0.01,0.0,0.0,200,315,475,23,72
44,0.12,0.28,0.44,0.018,0.008,0.03,0.99,0.54,0.08,0.0,0.007,0.01,0.0,0.0,400,257,482,24,73
46,0.12,0.28,0.44,0.018,0.008,0.03,0.99,0.54,0.08,0.0,0.007,0.01,0.0,0.0,500,256,442,25,82
48,0.12,0.28,0.44,0.018,0.008,0.03,0.99,0.54,0.08,0.0,0.007,0.01,0.0,0.0,600,213,308,37,89
50,0.12,0.37,0.45,0.018,0.008,0.035,1.0,0.5,0.06,0.0,0.009,0.0088,0.0,0.0,27,251,456,32,73
52,0.12,0.37,0.45,0.018,0.008,0.035,1.0,0.5,0.06,0.0,0.009,0.0088,0.0,0.0,200,261,449,24,71
54,0.12,0.37,0.45,0.018,0.008,0.035,1.0,0.5,0.06,0.0,0.009,0.0088,0.0,0.0,400,192,482,27,76
56,0.12,0.37,0.45,0.018,0.008,0.035,1.0,0.5,0.06,0.0,0.009,0.0088,0.0,0.0,500,192,435,25,83
58,0.12,0.37,0.45,0.018,0.008,0.035,1.0,0.5,0.06,0.0,0.009,0.0088,0.0,0.0,600,170,304,38,89
60,0.12,0.36,0.45,0.018,0.007,0.028,1.0,0.53,0.05,0.0,0.007,0.008,0.0,0.0,27,239,453,35,72
62,0.12,0.36,0.45,0.018,0.007,0.028,1.0,0.53,0.05,0.0,0.007,0.008,0.0,0.0,200,244,449,23,70
64,0.12,0.36,0.45,0.018,0.007,0.028,1.0,0.53,0.05,0.0,0.007,0.008,0.0,0.0,400,174,474,27,74
66,0.12,0.36,0.45,0.018,0.007,0.028,1.0,0.53,0.05,0.0,0.007,0.008,0.0,0.0,500,181,434,26,82
68,0.12,0.36,0.45,0.018,0.007,0.028,1.0,0.53,0.05,0.0,0.007,0.008,0.0,0.0,600,170,296,38,89
70,0.1,0.35,0.44,0.02,0.007,0.05,1.01,0.51,0.08,0.0,0.012,0.0082,0.0,0.0,27,241,431,36,76
72,0.1,0.35,0.44,0.02,0.007,0.05,1.01,0.51,0.08,0.0,0.012,0.0082,0.0,0.0,200,243,431,24,72
74,0.1,0.35,0.44,0.02,0.007,0.05,1.01,0.51,0.08,0.0,0.012,0.0082,0.0,0.0,400,168,454,27,77
76,0.1,0.35,0.44,0.02,0.007,0.05,1.01,0.51,0.08,0.0,0.012,0.0082,0.0,0.0,500,160,417,28,81
78,0.1,0.35,0.44,0.02,0.007,0.05,1.01,0.51,0.08,0.0,0.012,0.0082,0.0,0.0,600,161,293,38,88
80,0.09,0.32,0.48,0.02,0.017,0.023,1.05,0.52,0.04,0.0,0.009,0.0089,0.0,0.0,27,313,464,29,70
82,0.09,0.32,0.48,0.02,0.017,0.023,1.05,0.52,0.04,0.0,0.009,0.0089,0.0,0.0,200,324,459,22,67
84,0.09,0.32,0.48,0.02,0.017,0.023,1.05,0.52,0.04,0.0,0.009,0.0089,0.0,0.0,400,279,482,24,71
86,0.09,0.32,0.48,0.02,0.017,0.023,1.05,0.52,0.04,0.0,0.009,0.0089,0.0,0.0,500,262,449,24,76
88,0.09,0.32,0.48,0.02,0.017,0.023,1.05,0.52,0.04,0.0,0.009,0.0089,0.0,0.0,600,220,317,33,84
90,0.1,0.31,0.51,0.022,0.017,0.02,1.03,0.53,0.04,0.0,0.009,0.0076,0.0,0.0,27,291,462,30,71
92,0.1,0.31,0.51,0.022,0.017,0.02,1.03,0.53,0.04,0.0,0.009,0.0076,0.0,0.0,200,316,457,20,66
94,0.1,0.31,0.51,0.022,0.017,0.02,1.03,0.53,0.04,0.0,0.009,0.0076,0.0,0.0,400,270,482,24,71
96,0.1,0.31,0.51,0.022,0.017,0.02,1.03,0.53,0.04,0.0,0.009,0.0076,0.0,0.0,500,256,441,23,77
98,0.1,0.31,0.51,0.022,0.017,0.02,1.03,0.53,0.04,0.0,0.009,0.0076,0.0,0.0,600,218,299,42,87
100,0.1,0.3,0.49,0.02,0.018,0.023,1.04,0.5,0.04,0.0,0.009,0.0089,0.0,0.0,27,312,452,30,71
102,0.1,0.3,0.49,0.02,0.018,0.023,1.04,0.5,0.04,0.0,0.009,0.0089,0.0,0.0,200,311,454,22,64
104,0.1,0.3,0.49,0.02,0.018,0.023,1.04,0.5,0.04,0.0,0.009,0.0089,0.0,0.0,400,291,483,23,72
106,0.1,0.3,0.49,0.02,0.018,0.023,1.04,0.5,0.04,0.0,0.009,0.0089,0.0,0.0,500,260,448,24,77
108,0.1,0.3,0.49,0.02,0.018,0.023,1.04,0.5,0.04,0.0,0.009,0.0089,0.0,0.0,600,215,304,34,86
110,0.2,0.31,0.59,0.018,0.009,0.0,0.046,0.011,0.05,0.0,0.006,0.0056,0.0,0.0,27,280,480,31,64
112,0.2,0.31,0.59,0.018,0.009,0.0,0.046,0.011,0.05,0.0,0.006,0.0056,0.0,0.0,200,272,591,19,48
114,0.2,0.31,0.59,0.018,0.009,0.0,0.046,0.011,0.05,0.0,0.006,0.0056,0.0,0.0,350,185,509,34,66
116,0.2,0.31,0.59,0.018,0.009,0.0,0.046,0.011,0.05,0.0,0.006,0.0056,0.0,0.0,450,176,373,37,75
118,0.2,0.31,0.59,0.018,0.009,0.0,0.046,0.011,0.05,0.0,0.006,0.0056,0.0,0.0,550,131,234,61,90
120,0.2,0.28,0.6,0.018,0.008,0.0,0.045,0.01,0.05,0.0,0.005,0.0066,0.0,0.0,100,278,456,22,60
122,0.2,0.28,0.6,0.018,0.008,0.0,0.045,0.01,0.05,0.0,0.005,0.0066,0.0,0.0,300,187,540,30,58
124,0.2,0.28,0.6,0.018,0.008,0.0,0.045,0.01,0.05,0.0,0.005,0.0066,0.0,0.0,400,166,431,37,67
126,0.2,0.28,0.6,0.018,0.008,0.0,0.045,0.01,0.05,0.0,0.005,0.0066,0.0,0.0,500,152,302,40,83
128,0.2,0.29,0.55,0.021,0.009,0.0,0.054,0.012,0.05,0.0,0.004,0.0058,0.0,0.0,27,285,470,31,62
130,0.2,0.29,0.55,0.021,0.009,0.0,0.054,0.012,0.05,0.0,0.004,0.0058,0.0,0.0,200,267,564,18,48
132,0.2,0.29,0.55,0.021,0.009,0.0,0.054,0.012,0.05,0.0,0.004,0.0058,0.0,0.0,350,184,485,35,66
134,0.2,0.29,0.55,0.021,0.009,0.0,0.054,0.012,0.05,0.0,0.004,0.0058,0.0,0.0,450,179,372,36,78
136,0.2,0.29,0.55,0.021,0.009,0.0,0.054,0.012,0.05,0.0,0.004,0.0058,0.0,0.0,550,135,237,60,89
138,0.21,0.21,0.62,0.014,0.014,0.0,0.046,0.019,0.05,0.0,0.008,0.003,0.0,0.0,100,276,456,23,63
140,0.21,0.21,0.62,0.014,0.014,0.0,0.046,0.019,0.05,0.0,0.008,0.003,0.0,0.0,300,202,534,27,57
142,0.21,0.21,0.62,0.014,0.014,0.0,0.046,0.019,0.05,0.0,0.008,0.003,0.0,0.0,400,198,443,32,69
144,0.21,0.21,0.62,0.014,0.014,0.0,0.046,0.019,0.05,0.0,0.008,0.003,0.0,0.0,500,173,319,38,78
146,0.24,0.24,0.64,0.015,0.013,0.0,0.074,0.019,0.05,0.0,0.011,0.006,0.0,0.0,27,300,480,31,63
148,0.24,0.24,0.64,0.015,0.013,0.0,0.074,0.019,0.05,0.0,0.011,0.006,0.0,0.0,200,293,534,19,53
150,0.24,0.24,0.64,0.015,0.013,0.0,0.074,0.019,0.05,0.0,0.011,0.006,0.0,0.0,350,231,506,34,67
152,0.24,0.24,0.64,0.015,0.013,0.0,0.074,0.019,0.05,0.0,0.011,0.006,0.0,0.0,450,206,386,36,74
154,0.24,0.24,0.64,0.015,0.013,0.0,0.074,0.019,0.05,0.0,0.011,0.006,0.0,0.0,550,149,258,49,83
156,0.2,0.2,0.47,0.007,0.009,0.0,0.056,0.01,0.07,0.0,0.005,0.011,0.0,0.0,100,297,510,19,51
158,0.2,0.2,0.47,0.007,0.009,0.0,0.056,0.01,0.07,0.0,0.005,0.011,0.0,0.0,300,189,572,33,58
160,0.2,0.2,0.47,0.007,0.009,0.0,0.056,0.01,0.07,0.0,0.005,0.011,0.0,0.0,400,193,426,40,68
162,0.2,0.2,0.47,0.007,0.009,0.0,0.056,0.01,0.07,0.0,0.005,0.011,0.0,0.0,500,164,273,35,68
164,0.21,0.32,0.48,0.02,0.018,0.0,0.017,0.006,0.08,0.0,0.004,0.0044,0.0,0.0,27,275,460,33,64
166,0.21,0.32,0.48,0.02,0.018,0.0,0.017,0.006,0.08,0.0,0.004,0.0044,0.0,0.0,200,260,519,19,54
168,0.21,0.32,0.48,0.02,0.018,0.0,0.017,0.006,0.08,0.0,0.004,0.0044,0.0,0.0,350,188,469,32,67
170,0.21,0.32,0.48,0.02,0.018,0.0,0.017,0.006,0.08,0.0,0.004,0.0044,0.0,0.0,450,187,356,45,84
172,0.21,0.32,0.48,0.02,0.018,0.0,0.017,0.006,0.08,0.0,0.004,0.0044,0.0,0.0,550,137,227,50,88
174,0.2,0.31,0.5,0.022,0.017,0.0,0.017,0.006,0.09,0.0,0.004,0.0037,0.0,0.0,100,244,434,24,63
176,0.2,0.31,0.5,0.022,0.017,0.0,0.017,0.006,0.09,0.0,0.004,0.0037,0.0,0.0,300,202,509,30,60
178,0.2,0.31,0.5,0.022,0.017,0.0,0.017,0.006,0.09,0.0,0.004,0.0037,0.0,0.0,400,197,413,36,72
180,0.2,0.31,0.5,0.022,0.017,0.0,0.017,0.006,0.09,0.0,0.004,0.0037,0.0,0.0,500,160,276,42,84
182,0.23,0.32,0.53,0.023,0.016,0.0,0.022,0.005,0.07,0.0,0.005,0.0051,0.0,0.0,27,285,470,34,66
184,0.23,0.32,0.53,0.023,0.016,0.0,0.022,0.005,0.07,0.0,0.005,0.0051,0.0,0.0,200,251,502,20,56
186,0.23,0.32,0.53,0.023,0.016,0.0,0.022,0.005,0.07,0.0,0.005,0.0051,0.0,0.0,350,190,471,35,65
188,0.23,0.32,0.53,0.023,0.016,0.0,0.022,0.005,0.07,0.0,0.005,0.0051,0.0,0.0,450,202,343,40,77
190,0.23,0.32,0.53,0.023,0.016,0.0,0.022,0.005,0.07,0.0,0.005,0.0051,0.0,0.0,550,125,219,58,87
192,0.11,0.3,0.48,0.012,0.01,0.0,0.0,0.51,0.0,0.0,0.005,0.0078,0.0,0.0,100,260,442,26,67
194,0.11,0.3,0.48,0.012,0.01,0.0,0.0,0.51,0.0,0.0,0.005,0.0078,0.0,0.0,300,198,560,27,59
196,0.11,0.3,0.48,0.012,0.01,0.0,0.0,0.51,0.0,0.0,0.005,0.0078,0.0,0.0,450,181,447,28,78
198,0.11,0.3,0.48,0.012,0.01,0.0,0.0,0.51,0.0,0.0,0.005,0.0078,0.0,0.0,550,183,363,32,83
200,0.12,0.25,0.5,0.012,0.01,0.0,0.0,0.5,0.0,0.0,0.005,0.0068,0.0,0.0,27,270,460,34,69
202,0.12,0.25,0.5,0.012,0.01,0.0,0.0,0.5,0.0,0.0,0.005,0.0068,0.0,0.0,200,260,575,21,52
204,0.12,0.25,0.5,0.012,0.01,0.0,0.0,0.5,0.0,0.0,0.005,0.0068,0.0,0.0,400,204,484,31,73
206,0.12,0.25,0.5,0.012,0.01,0.0,0.0,0.5,0.0,0.0,0.005,0.0068,0.0,0.0,500,210,400,29,83
208,0.12,0.25,0.5,0.012,0.01,0.0,0.0,0.5,0.0,0.0,0.005,0.0068,0.0,0.0,600,163,272,48,89
210,0.13,0.31,0.48,0.006,0.007,0.0,0.0,0.49,0.0,0.0,0.005,0.006,0.0,0.0,100,248,439,24,66
212,0.13,0.31,0.48,0.006,0.007,0.0,0.0,0.49,0.0,0.0,0.005,0.006,0.0,0.0,300,177,571,28,58
214,0.13,0.31,0.48,0.006,0.007,0.0,0.0,0.49,0.0,0.0,0.005,0.006,0.0,0.0,450,189,451,28,78
216,0.13,0.31,0.48,0.006,0.007,0.0,0.0,0.49,0.0,0.0,0.005,0.006,0.0,0.0,550,193,353,32,84
218,0.15,0.22,0.43,0.011,0.022,0.01,0.02,0.5,0.03,0.0,0.004,0.004,0.0,0.0,27,280,430,36,71
220,0.15,0.22,0.43,0.011,0.022,0.01,0.02,0.5,0.03,0.0,0.004,0.004,0.0,0.0,200,273,533,20,61
222,0.15,0.22,0.43,0.011,0.022,0.01,0.02,0.5,0.03,0.0,0.004,0.004,0.0,0.0,400,181,428,31,68
224,0.15,0.22,0.43,0.011,0.022,0.01,0.02,0.5,0.03,0.0,0.004,0.004,0.0,0.0,500,180,350,30,78
226,0.15,0.22,0.43,0.011,0.022,0.01,0.02,0.5,0.03,0.0,0.004,0.004,0.0,0.0,600,140,250,44,86
228,0.14,0.22,0.46,0.012,0.012,0.01,0.03,0.5,0.03,0.0,0.006,0.006,0.0,0.0,100,274,423,21,67
230,0.14,0.22,0.46,0.012,0.012,0.01,0.03,0.5,0.03,0.0,0.006,0.006,0.0,0.0,300,218,530,27,37
232,0.14,0.22,0.46,0.012,0.012,0.01,0.03,0.5,0.03,0.0,0.006,0.006,0.0,0.0,450,200,393,28,72
234,0.14,0.22,0.46,0.012,0.012,0.01,0.03,0.5,0.03,0.0,0.006,0.006,0.0,0.0,550,213,311,30,82
236,0.15,0.25,0.58,0.008,0.01,0.05,0.11,0.52,0.04,0.0,0.007,0.011,0.0,0.0,27,290,450,36,74
238,0.15,0.25,0.58,0.008,0.01,0.05,0.11,0.52,0.04,0.0,0.007,0.011,0.0,0.0,200,260,463,22,68
240,0.15,0.25,0.58,0.008,0.01,0.05,0.11,0.52,0.04,0.0,0.007,0.011,0.0,0.0,400,182,438,32,73
242,0.15,0.25,0.58,0.008,0.01,0.05,0.11,0.52,0.04,0.0,0.007,0.011,0.0,0.0,500,167,372,29,80
244,0.15,0.25,0.58,0.008,0.01,0.05,0.11,0.52,0.04,0.0,0.007,0.011,0.0,0.0,600,146,253,44,87
246,0.2,0.28,0.59,0.012,0.01,0.02,0.02,0.54,0.07,0.0,0.003,0.0054,0.0,0.0,100,308,445,20,59
248,0.2,0.28,0.59,0.012,0.01,0.02,0.02,0.54,0.07,0.0,0.003,0.0054,0.0,0.0,300,278,557,24,28
250,0.2,0.28,0.59,0.012,0.01,0.02,0.02,0.54,0.07,0.0,0.003,0.0054,0.0,0.0,450,249,416,29,72
252,0.2,0.28,0.59,0.012,0.01,0.02,0.02,0.54,0.07,0.0,0.003,0.0054,0.0,0.0,550,237,321,30,84
254,0.17,0.3,0.63,0.012,0.012,0.04,0.09,0.52,0.1,0.0,0.003,0.007,0.0,0.0,27,320,480,30,64
256,0.17,0.3,0.63,0.012,0.012,0.04,0.09,0.52,0.1,0.0,0.003,0.007,0.0,0.0,200,310,592,17,45
258,0.17,0.3,0.63,0.012,0.012,0.04,0.09,0.52,0.1,0.0,0.003,0.007,0.0,0.0,400,238,487,27,61
260,0.17,0.3,0.63,0.012,0.012,0.04,0.09,0.52,0.1,0.0,0.003,0.007,0.0,0.0,500,248,385,34,77
262,0.17,0.3,0.63,0.012,0.012,0.04,0.09,0.52,0.1,0.0,0.003,0.007,0.0,0.0,600,177,268,39,83
264,0.13,0.23,0.66,0.01,0.01,0.08,0.06,0.51,0.13,0.0,0.004,0.0057,0.0,0.0,100,408,512,20,64
266,0.13,0.23,0.66,0.01,0.01,0.08,0.06,0.51,0.13,0.0,0.004,0.0057,0.0,0.0,300,263,541,27,54
268,0.13,0.23,0.66,0.01,0.01,0.08,0.06,0.51,0.13,0.0,0.004,0.0057,0.0,0.0,450,261,407,31,71
270,0.13,0.23,0.66,0.01,0.01,0.08,0.06,0.51,0.13,0.0,0.004,0.0057,0.0,0.0,550,215,317,32,81
272,0.14,0.39,0.63,0.008,0.005,0.0,0.0,0.58,0.03,0.0,0.004,0.006,0.0,0.0,27,420,530,23,65
274,0.14,0.39,0.63,0.008,0.005,0.0,0.0,0.58,0.03,0.0,0.004,0.006,0.0,0.0,200,412,616,17,52
276,0.14,0.39,0.63,0.008,0.005,0.0,0.0,0.58,0.03,0.0,0.004,0.006,0.0,0.0,400,367,532,26,64
278,0.14,0.39,0.63,0.008,0.005,0.0,0.0,0.58,0.03,0.0,0.004,0.006,0.0,0.0,500,306,420,27,79
280,0.14,0.39,0.63,0.008,0.005,0.0,0.0,0.58,0.03,0.0,0.004,0.006,0.0,0.0,600,243,304,32,83
282,0.14,0.4,0.67,0.007,0.004,0.0,0.0,0.6,0.03,0.0,0.004,0.007,0.0,0.0,100,380,506,19,61
284,0.14,0.4,0.67,0.007,0.004,0.0,0.0,0.6,0.03,0.0,0.004,0.007,0.0,0.0,300,378,614,23,51
286,0.14,0.4,0.67,0.007,0.004,0.0,0.0,0.6,0.03,0.0,0.004,0.007,0.0,0.0,450,328,477,27,71
288,0.14,0.4,0.67,0.007,0.004,0.0,0.0,0.6,0.03,0.0,0.004,0.007,0.0,0.0,550,268,369,35,86
290,0.14,0.39,0.64,0.006,0.005,0.0,0.0,0.58,0.03,0.0,0.005,0.008,0.0,0.0,27,380,520,25,64
292,0.14,0.39,0.64,0.006,0.005,0.0,0.0,0.58,0.03,0.0,0.005,0.008,0.0,0.0,200,367,606,18,48
294,0.14,0.39,0.64,0.006,0.005,0.0,0.0,0.58,0.03,0.0,0.005,0.008,0.0,0.0,400,323,517,26,64
296,0.14,0.39,0.64,0.006,0.005,0.0,0.0,0.58,0.03,0.0,0.005,0.008,0.0,0.0,500,276,417,28,80
298,0.14,0.39,0.64,0.006,0.005,0.0,0.0,0.58,0.03,0.0,0.005,0.008,0.0,0.0,600,217,291,46,84
300,0.28,0.3,0.7,0.022,0.011,0.14,0.07,0.02,0.22,0.0,0.004,0.0097,0.0,0.0,100,284,484,29,58
302,0.28,0.3,0.7,0.022,0.011,0.14,0.07,0.02,0.22,0.0,0.004,0.0097,0.0,0.0,300,223,483,26,48
304,0.28,0.3,0.7,0.022,0.011,0.14,0.07,0.02,0.22,0.0,0.004,0.0097,0.0,0.0,400,199,432,33,61
306,0.28,0.3,0.7,0.022,0.011,0.14,0.07,0.02,0.22,0.0,0.004,0.0097,0.0,0.0,500,165,314,39,69
308,0.2,0.22,0.68,0.024,0.009,0.15,0.11,0.03,0.23,0.0,0.01,0.0077,0.0,0.0,27,275,490,33,64
310,0.2,0.22,0.68,0.024,0.009,0.15,0.11,0.03,0.23,0.0,0.01,0.0077,0.0,0.0,200,243,439,28,62
312,0.2,0.22,0.68,0.024,0.009,0.15,0.11,0.03,0.23,0.0,0.01,0.0077,0.0,0.0,350,194,454,31,58
314,0.2,0.22,0.68,0.024,0.009,0.15,0.11,0.03,0.23,0.0,0.01,0.0077,0.0,0.0,450,183,368,43,74
316,0.2,0.22,0.68,0.024,0.009,0.15,0.11,0.03,0.23,0.0,0.01,0.0077,0.0,0.0,550,149,249,54,83
318,0.34,0.22,0.7,0.016,0.012,0.14,0.1,0.03,0.2,0.0,0.002,0.0107,0.0,0.0,100,266,454,31,61
320,0.34,0.22,0.7,0.016,0.012,0.14,0.1,0.03,0.2,0.0,0.002,0.0107,0.0,0.0,300,194,458,28,52
322,0.34,0.22,0.7,0.016,0.012,0.14,0.1,0.03,0.2,0.0,0.002,0.0107,0.0,0.0,400,194,422,31,62
324,0.34,0.22,0.7,0.016,0.012,0.14,0.1,0.03,0.2,0.0,0.002,0.0107,0.0,0.0,500,163,310,34,70
326,0.28,0.19,0.8,0.01,0.012,0.0,0.06,0.22,0.04,0.0,0.016,0.0073,0.0,0.0,27,275,490,30,56
328,0.28,0.19,0.8,0.01,0.012,0.0,0.06,0.22,0.04,0.0,0.016,0.0073,0.0,0.0,200,228,440,26,53
330,0.28,0.19,0.8,0.01,0.012,0.0,0.06,0.22,0.04,0.0,0.016,0.0073,0.0,0.0,350,179,457,30,60
332,0.28,0.19,0.8,0.01,0.012,0.0,0.06,0.22,0.04,0.0,0.016,0.0073,0.0,0.0,450,183,382,33,74
334,0.28,0.19,0.8,0.01,0.012,0.0,0.06,0.22,0.04,0.0,0.016,0.0073,0.0,0.0,550,149,256,37,81
336,0.29,0.2,0.93,0.014,0.015,0.03,0.03,0.36,0.06,0.0,0.018,0.0045,0.0,0.0,100,300,498,27,54
338,0.29,0.2,0.93,0.014,0.015,0.03,0.03,0.36,0.06,0.0,0.018,0.0045,0.0,0.0,300,235,522,22,47
340,0.29,0.2,0.93,0.014,0.015,0.03,0.03,0.36,0.06,0.0,0.018,0.0045,0.0,0.0,400,213,480,29,64
342,0.29,0.2,0.93,0.014,0.015,0.03,0.03,0.36,0.06,0.0,0.018,0.0045,0.0,0.0,500,213,380,28,73
344,0.29,0.22,1.0,0.016,0.011,0.05,0.07,0.34,0.05,0.0,0.011,0.0035,0.0,0.0,27,305,530,27,54
346,0.29,0.22,1.0,0.016,0.011,0.05,0.07,0.34,0.05,0.0,0.011,0.0035,0.0,0.0,200,259,478,23,50
348,0.29,0.22,1.0,0.016,0.011,0.05,0.07,0.34,0.05,0.0,0.011,0.0035,0.0,0.0,350,214,503,29,60
350,0.29,0.22,1.0,0.016,0.011,0.05,0.07,0.34,0.05,0.0,0.011,0.0035,0.0,0.0,450,202,424,33,73
352,0.29,0.22,1.0,0.016,0.011,0.05,0.07,0.34,0.05,0.0,0.011,0.0035,0.0,0.0,550,194,315,42,83
354,0.22,0.22,0.82,0.015,0.006,0.05,0.06,0.18,0.08,0.0,0.005,0.0082,0.0,0.0,100,289,443,28,63
356,0.22,0.22,0.82,0.015,0.006,0.05,0.06,0.18,0.08,0.0,0.005,0.0082,0.0,0.0,300,223,468,23,56
358,0.22,0.22,0.82,0.015,0.006,0.05,0.06,0.18,0.08,0.0,0.005,0.0082,0.0,0.0,400,194,408,33,71
360,0.22,0.22,0.82,0.015,0.006,0.05,0.06,0.18,0.08,0.0,0.005,0.0082,0.0,0.0,500,186,330,37,79
362,0.26,0.23,0.74,0.016,0.006,0.05,0.04,0.15,0.07,0.0,0.007,0.0108,0.0,0.0,27,270,480,30,58
364,0.26,0.23,0.74,0.016,0.006,0.05,0.04,0.15,0.07,0.0,0.007,0.0108,0.0,0.0,200,224,431,25,55
366,0.26,0.23,0.74,0.016,0.006,0.05,0.04,0.15,0.07,0.0,0.007,0.0108,0.0,0.0,350,205,526,26,53
368,0.26,0.23,0.74,0.016,0.006,0.05,0.04,0.15,0.07,0.0,0.007,0.0108,0.0,0.0,450,168,376,36,72
370,0.26,0.23,0.74,0.016,0.006,0.05,0.04,0.15,0.07,0.0,0.007,0.0108,0.0,0.0,550,153,268,51,82
372,0.28,0.2,0.72,0.015,0.012,0.32,1.02,1.12,0.2,0.27,0.002,0.0075,0.0,0.0,100,621,754,16,57
374,0.28,0.2,0.72,0.015,0.012,0.32,1.02,1.12,0.2,0.27,0.002,0.0075,0.0,0.0,300,580,722,15,52
376,0.28,0.2,0.72,0.015,0.012,0.32,1.02,1.12,0.2,0.27,0.002,0.0075,0.0,0.0,450,514,629,17,62
378,0.28,0.2,0.72,0.015,0.012,0.32,1.02,1.12,0.2,0.27,0.002,0.0075,0.0,0.0,550,469,504,19,80
380,0.28,0.2,0.72,0.015,0.012,0.32,1.02,1.12,0.2,0.27,0.002,0.0075,0.0,0.0,650,257,375,32,91
382,0.28,0.18,0.75,0.012,0.009,0.32,1.0,1.25,0.14,0.27,0.002,0.009,0.0,0.0,100,617,761,16,54
384,0.28,0.18,0.75,0.012,0.009,0.32,1.0,1.25,0.14,0.27,0.002,0.009,0.0,0.0,300,566,724,14,52
386,0.28,0.18,0.75,0.012,0.009,0.32,1.0,1.25,0.14,0.27,0.002,0.009,0.0,0.0,450,517,634,16,55
388,0.28,0.18,0.75,0.012,0.009,0.32,1.0,1.25,0.14,0.27,0.002,0.009,0.0,0.0,550,438,514,20,76
390,0.28,0.18,0.75,0.012,0.009,0.32,1.0,1.25,0.14,0.27,0.002,0.009,0.0,0.0,650,254,364,35,92
392,0.29,0.2,0.75,0.01,0.009,0.34,1.0,1.25,0.14,0.26,0.002,0.0075,0.0,0.0,100,662,786,16,58
394,0.29,0.2,0.75,0.01,0.009,0.34,1.0,1.25,0.14,0.26,0.002,0.0075,0.0,0.0,300,602,743,15,56
396,0.29,0.2,0.75,0.01,0.009,0.34,1.0,1.25,0.14,0.26,0.002,0.0075,0.0,0.0,450,544,644,16,62
398,0.29,0.2,0.75,0.01,0.009,0.34,1.0,1.25,0.14,0.26,0.002,0.0075,0.0,0.0,550,446,529,19,80
400,0.29,0.2,0.75,0.01,0.009,0.34,1.0,1.25,0.14,0.26,0.002,0.0075,0.0,0.0,650,256,376,37,93
402,0.3,0.28,0.72,0.014,0.006,0.35,0.93,1.22,0.16,0.21,0.002,0.0093,0.0,0.0,100,613,751,16,56
404,0.3,0.28,0.72,0.014,0.006,0.35,0.93,1.22,0.16,0.21,0.002,0.0093,0.0,0.0,300,569,731,13,49
406,0.3,0.28,0.72,0.014,0.006,0.35,0.93,1.22,0.16,0.21,0.002,0.0093,0.0,0.0,450,522,631,17,62
408,0.3,0.28,0.72,0.014,0.006,0.35,0.93,1.22,0.16,0.21,0.002,0.0093,0.0,0.0,550,432,510,19,77
410,0.3,0.28,0.72,0.014,0.006,0.35,0.93,1.22,0.16,0.21,0.002,0.0093,0.0,0.0,650,277,373,34,91
412,0.3,0.26,0.79,0.016,0.015,0.32,1.03,1.13,0.19,0.23,0.002,0.0085,0.0,0.0,100,585,738,16,57
414,0.3,0.26,0.79,0.016,0.015,0.32,1.03,1.13,0.19,0.23,0.002,0.0085,0.0,0.0,300,562,710,13,42
416,0.3,0.26,0.79,0.016,0.015,0.32,1.03,1.13,0.19,0.23,0.002,0.0085,0.0,0.0,450,501,619,16,61
418,0.3,0.26,0.79,0.016,0.015,0.32,1.03,1.13,0.19,0.23,0.002,0.0085,0.0,0.0,550,426,503,22,77
420,0.3,0.26,0.79,0.016,0.015,0.32,1.03,1.13,0.19,0.23,0.002,0.0085,0.0,0.0,650,250,367,27,90
422,0.29,0.26,0.76,0.009,0.007,0.45,1.12,1.18,0.07,0.23,0.003,0.0103,0.0,0.0,100,642,786,15,59
424,0.29,0.26,0.76,0.009,0.007,0.45,1.12,1.18,0.07,0.23,0.003,0.0103,0.0,0.0,300,596,746,14,51
426,0.29,0.26,0.76,0.009,0.007,0.45,1.12,1.18,0.07,0.23,0.003,0.0103,0.0,0.0,450,545,647,15,67
428,0.29,0.26,0.76,0.009,0.007,0.45,1.12,1.18,0.07,0.23,0.003,0.0103,0.0,0.0,550,463,537,21,83
430,0.29,0.26,0.76,0.009,0.007,0.45,1.12,1.18,0.07,0.23,0.003,0.0103,0.0,0.0,650,279,391,28,92
432,0.29,0.26,0.77,0.009,0.007,0.46,1.12,1.2,0.08,0.23,0.004,0.0095,0.0,0.0,100,622,775,16,61
434,0.29,0.26,0.77,0.009,0.007,0.46,1.12,1.2,0.08,0.23,0.004,0.0095,0.0,0.0,300,579,727,13,48
436,0.29,0.26,0.77,0.009,0.007,0.46,1.12,1.2,0.08,0.23,0.004,0.0095,0.0,0.0,450,522,632,16,54
438,0.29,0.26,0.77,0.009,0.007,0.46,1.12,1.2,0.08,0.23,0.004,0.0095,0.0,0.0,550,446,525,19,80
440,0.29,0.26,0.77,0.009,0.007,0.46,1.12,1.2,0.08,0.23,0.004,0.0095,0.0,0.0,650,284,391,25,89
442,0.29,0.21,0.66,0.01,0.008,0.51,1.07,1.29,0.06,0.23,0.005,0.0097,0.0,0.0,100,601,748,17,62
444,0.29,0.21,0.66,0.01,0.008,0.51,1.07,1.29,0.06,0.23,0.005,0.0097,0.0,0.0,300,560,716,14,55
446,0.29,0.21,0.66,0.01,0.008,0.51,1.07,1.29,0.06,0.23,0.005,0.0097,0.0,0.0,450,508,612,18,67
448,0.29,0.21,0.66,0.01,0.008,0.51,1.07,1.29,0.06,0.23,0.005,0.0097,0.0,0.0,550,430,506,20,83
450,0.29,0.21,0.66,0.01,0.008,0.51,1.07,1.29,0.06,0.23,0.005,0.0097,0.0,0.0,650,267,370,32,91
452,0.3,0.27,0.7,0.012,0.012,0.44,1.1,1.35,0.11,0.27,0.003,0.0082,0.0,0.0,100,634,766,16,61
454,0.3,0.27,0.7,0.012,0.012,0.44,1.1,1.35,0.11,0.27,0.003,0.0082,0.0,0.0,300,585,737,14,53
456,0.3,0.27,0.7,0.012,0.012,0.44,1.1,1.35,0.11,0.27,0.003,0.0082,0.0,0.0,450,522,631,17,68
458,0.3,0.27,0.7,0.012,0.012,0.44,1.1,1.35,0.11,0.27,0.003,0.0082,0.0,0.0,550,437,522,20,84
460,0.3,0.27,0.7,0.012,0.012,0.44,1.1,1.35,0.11,0.27,0.003,0.0082,0.0,0.0,650,271,382,28,90
462,0.18,0.26,1.33,0.015,0.008,0.55,0.11,0.49,0.11,0.0,0.028,0.006,0.0,0.0,100,393,525,23,69
464,0.18,0.26,1.33,0.015,0.008,0.55,0.11,0.49,0.11,0.0,0.028,0.006,0.0,0.0,300,395,588,21,62
466,0.18,0.26,1.33,0.015,0.008,0.55,0.11,0.49,0.11,0.0,0.028,0.006,0.0,0.0,400,367,534,25,71
468,0.18,0.26,1.33,0.015,0.008,0.55,0.11,0.49,0.11,0.0,0.028,0.006,0.0,0.0,500,322,409,23,78
470,0.18,0.26,1.33,0.015,0.008,0.55,0.11,0.49,0.11,0.0,0.028,0.006,0.0,0.0,600,240,313,31,84
472,0.17,0.23,1.34,0.014,0.009,0.57,0.16,0.49,0.11,0.0,0.038,0.007,0.0,0.0,100,427,548,23,71
474,0.17,0.23,1.34,0.014,0.009,0.57,0.16,0.49,0.11,0.0,0.038,0.007,0.0,0.0,300,435,608,20,61
476,0.17,0.23,1.34,0.014,0.009,0.57,0.16,0.49,0.11,0.0,0.038,0.007,0.0,0.0,400,366,531,26,68
478,0.17,0.23,1.34,0.014,0.009,0.57,0.16,0.49,0.11,0.0,0.038,0.007,0.0,0.0,500,337,427,22,79
480,0.17,0.23,1.34,0.014,0.009,0.57,0.16,0.49,0.11,0.0,0.038,0.007,0.0,0.0,600,248,308,37,85
482,0.17,0.33,1.37,0.016,0.014,0.6,0.08,0.53,0.24,0.0,0.008,0.0071,0.0,0.0,100,421,558,21,68
484,0.17,0.33,1.37,0.016,0.014,0.6,0.08,0.53,0.24,0.0,0.008,0.0071,0.0,0.0,300,400,565,18,60
486,0.17,0.33,1.37,0.016,0.014,0.6,0.08,0.53,0.24,0.0,0.008,0.0071,0.0,0.0,400,378,532,19,45
488,0.17,0.33,1.37,0.016,0.014,0.6,0.08,0.53,0.24,0.0,0.008,0.0071,0.0,0.0,500,341,473,23,75
490,0.17,0.33,1.37,0.016,0.014,0.6,0.08,0.53,0.24,0.0,0.008,0.0071,0.0,0.0,600,250,310,30,88
492,0.17,0.35,1.44,0.015,0.01,0.58,0.08,0.5,0.23,0.0,0.006,0.0079,0.0,0.0,27,420,580,27,71
494,0.17,0.35,1.44,0.015,0.01,0.58,0.08,0.5,0.23,0.0,0.006,0.0079,0.0,0.0,200,381,525,22,69
496,0.17,0.35,1.44,0.015,0.01,0.58,0.08,0.5,0.23,0.0,0.006,0.0079,0.0,0.0,350,357,549,24,62
498,0.17,0.35,1.44,0.015,0.01,0.58,0.08,0.5,0.23,0.0,0.006,0.0079,0.0,0.0,450,336,462,22,66
500,0.17,0.35,1.44,0.015,0.01,0.58,0.08,0.5,0.23,0.0,0.006,0.0079,0.0,0.0,550,286,355,31,84
502,0.19,0.33,1.41,0.014,0.006,0.58,0.1,0.53,0.25,0.0,0.008,0.0077,0.0,0.0,27,435,590,26,72
504,0.19,0.33,1.41,0.014,0.006,0.58,0.1,0.53,0.25,0.0,0.008,0.0077,0.0,0.0,200,395,540,23,69
506,0.19,0.33,1.41,0.014,0.006,0.58,0.1,0.53,0.25,0.0,0.008,0.0077,0.0,0.0,350,370,558,23,60
508,0.19,0.33,1.41,0.014,0.006,0.58,0.1,0.53,0.25,0.0,0.008,0.0077,0.0,0.0,450,335,470,22,64
510,0.19,0.33,1.41,0.014,0.006,0.58,0.1,0.53,0.25,0.0,0.008,0.0077,0.0,0.0,550,288,356,29,83
512,0.12,0.25,0.48,0.008,0.012,0.04,0.64,0.51,0.04,0.0,0.006,0.013,0.0,0.0,27,270,480,32,75
514,0.12,0.25,0.48,0.008,0.012,0.04,0.64,0.51,0.04,0.0,0.006,0.013,0.0,0.0,200,261,542,20,59
516,0.12,0.25,0.48,0.008,0.012,0.04,0.64,0.51,0.04,0.0,0.006,0.013,0.0,0.0,400,237,564,26,66
518,0.12,0.25,0.48,0.008,0.012,0.04,0.64,0.51,0.04,0.0,0.006,0.013,0.0,0.0,500,237,487,25,70
520,0.12,0.25,0.48,0.008,0.012,0.04,0.64,0.51,0.04,0.0,0.006,0.013,0.0,0.0,600,193,332,42,84
522,0.16,0.24,0.49,0.012,0.007,0.035,0.61,0.51,0.04,0.0,0.006,0.0086,0.0,0.0,100,260,408,29,67
524,0.16,0.24,0.49,0.012,0.007,0.035,0.61,0.51,0.04,0.0,0.006,0.0086,0.0,0.0,300,192,493,21,57
526,0.16,0.24,0.49,0.012,0.007,0.035,0.61,0.51,0.04,0.0,0.006,0.0086,0.0,0.0,450,180,434,28,79
528,0.16,0.24,0.49,0.012,0.007,0.035,0.61,0.51,0.04,0.0,0.006,0.0086,0.0,0.0,550,176,349,37,87
530,0.12,0.25,0.43,0.006,0.011,0.03,0.59,0.51,0.03,0.0,0.006,0.015,0.0,0.0,27,325,460,36,77
532,0.12,0.25,0.43,0.006,0.011,0.03,0.59,0.51,0.03,0.0,0.006,0.015,0.0,0.0,200,284,435,25,76
534,0.12,0.25,0.43,0.006,0.011,0.03,0.59,0.51,0.03,0.0,0.006,0.015,0.0,0.0,400,213,455,29,78
536,0.12,0.25,0.43,0.006,0.011,0.03,0.59,0.51,0.03,0.0,0.006,0.015,0.0,0.0,500,208,402,26,83
538,0.12,0.25,0.43,0.006,0.011,0.03,0.59,0.51,0.03,0.0,0.006,0.015,0.0,0.0,600,168,283,46,90
540,0.12,0.25,0.44,0.013,0.012,0.05,0.71,0.52,0.06,0.0,0.004,0.0058,0.0,0.0,100,276,438,26,66
542,0.12,0.25,0.44,0.013,0.012,0.05,0.71,0.52,0.06,0.0,0.004,0.0058,0.0,0.0,300,260,557,20,50
544,0.12,0.25,0.44,0.013,0.012,0.05,0.71,0.52,0.06,0.0,0.004,0.0058,0.0,0.0,450,228,507,24,63
546,0.12,0.25,0.44,0.013,0.012,0.05,0.71,0.52,0.06,0.0,0.004,0.0058,0.0,0.0,550,220,418,27,76
548,0.12,0.24,0.47,0.008,0.011,0.04,0.71,0.49,0.06,0.0,0.006,0.013,0.0,0.0,27,275,480,33,75
550,0.12,0.24,0.47,0.008,0.011,0.04,0.71,0.49,0.06,0.0,0.006,0.013,0.0,0.0,200,270,522,21,64
552,0.12,0.24,0.47,0.008,0.011,0.04,0.71,0.49,0.06,0.0,0.006,0.013,0.0,0.0,400,246,556,26,64
554,0.12,0.24,0.47,0.008,0.011,0.04,0.71,0.49,0.06,0.0,0.006,0.013,0.0,0.0,500,232,474,25,73
556,0.12,0.24,0.47,0.008,0.011,0.04,0.71,0.49,0.06,0.0,0.006,0.013,0.0,0.0,600,198,313,47,88
558,0.15,0.26,0.45,0.012,0.006,0.033,0.58,0.49,0.04,0.0,0.006,0.0084,0.0,0.0,100,261,418,32,65
560,0.15,0.26,0.45,0.012,0.006,0.033,0.58,0.49,0.04,0.0,0.006,0.0084,0.0,0.0,300,192,492,21,57
562,0.15,0.26,0.45,0.012,0.006,0.033,0.58,0.49,0.04,0.0,0.006,0.0084,0.0,0.0,450,178,424,30,81
564,0.15,0.26,0.45,0.012,0.006,0.033,0.58,0.49,0.04,0.0,0.006,0.0084,0.0,0.0,550,178,337,37,88
566,0.14,0.22,0.45,0.013,0.013,0.06,0.68,0.52,0.06,0.0,0.004,0.0062,0.0,0.0,27,250,470,33,65
568,0.14,0.22,0.45,0.013,0.013,0.06,0.68,0.52,0.06,0.0,0.004,0.0062,0.0,0.0,200,251,522,19,52
570,0.14,0.22,0.45,0.013,0.013,0.06,0.68,0.52,0.06,0.0,0.004,0.0062,0.0,0.0,400,254,524,25,60
572,0.14,0.22,0.45,0.013,0.013,0.06,0.68,0.52,0.06,0.0,0.004,0.0062,0.0,0.0,500,207,462,27,71
574,0.14,0.22,0.45,0.013,0.013,0.06,0.68,0.52,0.06,0.0,0.004,0.0062,0.0,0.0,600,202,328,41,82
576,0.15,0.21,0.42,0.015,0.011,0.06,0.66,0.52,0.07,0.0,0.004,0.0056,0.0,0.0,100,221,411,26,63
578,0.15,0.21,0.42,0.015,0.011,0.06,0.66,0.52,0.07,0.0,0.004,0.0056,0.0,0.0,300,223,544,20,50
580,0.15,0.21,0.42,0.015,0.011,0.06,0.66,0.52,0.07,0.0,0.004,0.0056,0.0,0.0,450,202,486,26,64
582,0.15,0.21,0.42,0.015,0.011,0.06,0.66,0.52,0.07,0.0,0.004,0.0056,0.0,0.0,550,203,395,31,78
584,0.15,0.25,0.45,0.013,0.008,0.032,0.6,0.48,0.04,0.0,0.006,0.0082,0.0,0.0,27,265,450,33,66
586,0.15,0.25,0.45,0.013,0.008,0.032,0.6,0.48,0.04,0.0,0.006,0.0082,0.0,0.0,200,254,448,22,59
588,0.15,0.25,0.45,0.013,0.008,0.032,0.6,0.48,0.04,0.0,0.006,0.0082,0.0,0.0,400,180,452,31,75
590,0.15,0.25,0.45,0.013,0.008,0.032,0.6,0.48,0.04,0.0,0.006,0.0082,0.0,0.0,500,172,385,33,85
592,0.15,0.25,0.45,0.013,0.008,0.032,0.6,0.48,0.04,0.0,0.006,0.0082,0.0,0.0,600,160,269,46,89
594,0.17,0.39,0.6,0.022,0.02,0.11,1.31,1.02,0.11,0.28,0.004,0.0078,0.0,0.0,100,532,666,17,50
596,0.17,0.39,0.6,0.022,0.02,0.11,1.31,1.02,0.11,0.28,0.004,0.0078,0.0,0.0,300,499,644,15,46
598,0.17,0.39,0.6,0.022,0.02,0.11,1.31,1.02,0.11,0.28,0.004,0.0078,0.0,0.0,450,437,567,18,57
600,0.17,0.39,0.6,0.022,0.02,0.11,1.31,1.02,0.11,0.28,0.004,0.0078,0.0,0.0,550,428,492,17,54
602,0.17,0.39,0.6,0.022,0.02,0.11,1.31,1.02,0.11,0.28,0.004,0.0078,0.0,0.0,650,259,330,29,88
604,0.16,0.47,0.62,0.01,0.01,0.19,1.01,0.92,0.15,0.24,0.003,0.0111,0.0,0.0,100,521,661,17,62
606,0.16,0.47,0.62,0.01,0.01,0.19,1.01,0.92,0.15,0.24,0.003,0.0111,0.0,0.0,300,491,626,13,52
608,0.16,0.47,0.62,0.01,0.01,0.19,1.01,0.92,0.15,0.24,0.003,0.0111,0.0,0.0,450,449,566,16,54
610,0.16,0.47,0.62,0.01,0.01,0.19,1.01,0.92,0.15,0.24,0.003,0.0111,0.0,0.0,550,382,449,18,72
612,0.16,0.47,0.62,0.01,0.01,0.19,1.01,0.92,0.15,0.24,0.003,0.0111,0.0,0.0,650,261,339,23,86
614,0.14,0.34,0.73,0.01,0.009,0.13,1.06,0.96,0.08,0.23,0.003,0.0102,0.0,0.0,100,570,678,13,37
616,0.14,0.34,0.73,0.01,0.009,0.13,1.06,0.96,0.08,0.23,0.003,0.0102,0.0,0.0,300,506,626,13,34
618,0.14,0.34,0.73,0.01,0.009,0.13,1.06,0.96,0.08,0.23,0.003,0.0102,0.0,0.0,450,462,554,16,55
620,0.14,0.34,0.73,0.01,0.009,0.13,1.06,0.96,0.08,0.23,0.003,0.0102,0.0,0.0,550,403,462,20,75
622,0.14,0.34,0.73,0.01,0.009,0.13,1.06,0.96,0.08,0.23,0.003,0.0102,0.0,0.0,650,283,352,22,82
624,0.18,0.37,0.66,0.018,0.017,0.1,1.07,1.03,0.12,0.3,0.02,0.0081,0.0,0.0,100,584,716,13,47
627,0.18,0.37,0.66,0.018,0.017,0.1,1.07,1.03,0.12,0.3,0.02,0.0081,0.0,0.0,400,482,629,16,50
629,0.18,0.37,0.66,0.018,0.017,0.1,1.07,1.03,0.12,0.3,0.02,0.0081,0.0,0.0,500,444,546,17,62
631,0.18,0.37,0.66,0.018,0.017,0.1,1.07,1.03,0.12,0.3,0.02,0.0081,0.0,0.0,600,359,416,19,77
633,0.16,0.47,0.62,0.01,0.01,0.19,1.0,0.92,0.15,0.24,0.002,0.0104,0.0,0.0,27,515,680,16,50
635,0.16,0.47,0.62,0.01,0.01,0.19,1.0,0.92,0.15,0.24,0.002,0.0104,0.0,0.0,200,494,623,14,40
637,0.16,0.47,0.62,0.01,0.01,0.19,1.0,0.92,0.15,0.24,0.002,0.0104,0.0,0.0,400,440,580,15,53
639,0.16,0.47,0.62,0.01,0.01,0.19,1.0,0.92,0.15,0.24,0.002,0.0104,0.0,0.0,500,421,504,16,58
641,0.16,0.47,0.62,0.01,0.01,0.19,1.0,0.92,0.15,0.24,0.002,0.0104,0.0,0.0,600,335,389,17,77
643,0.18,0.37,0.61,0.019,0.018,0.11,1.09,1.12,0.07,0.28,0.016,0.0064,0.0,0.0,27,650,790,16,49
645,0.18,0.37,0.61,0.019,0.018,0.11,1.09,1.12,0.07,0.28,0.016,0.0064,0.0,0.0,200,516,644,15,51
647,0.18,0.37,0.61,0.019,0.018,0.11,1.09,1.12,0.07,0.28,0.016,0.0064,0.0,0.0,400,530,655,14,42
649,0.18,0.37,0.61,0.019,0.018,0.11,1.09,1.12,0.07,0.28,0.016,0.0064,0.0,0.0,500,440,540,13,51
651,0.18,0.37,0.61,0.019,0.018,0.11,1.09,1.12,0.07,0.28,0.016,0.0064,0.0,0.0,600,403,466,19,74
653,0.16,0.52,0.79,0.01,0.008,0.13,1.16,0.97,0.11,0.23,0.003,0.0106,0.0,0.0,27,570,720,17,62
655,0.16,0.52,0.79,0.01,0.008,0.13,1.16,0.97,0.11,0.23,0.003,0.0106,0.0,0.0,200,522,638,13,40
657,0.16,0.52,0.79,0.01,0.008,0.13,1.16,0.97,0.11,0.23,0.003,0.0106,0.0,0.0,400,499,632,18,53
659,0.16,0.52,0.79,0.01,0.008,0.13,1.16,0.97,0.11,0.23,0.003,0.0106,0.0,0.0,500,453,535,19,70
661,0.16,0.52,0.79,0.01,0.008,0.13,1.16,0.97,0.11,0.23,0.003,0.0106,0.0,0.0,600,338,405,26,84
663,0.18,0.39,0.63,0.012,0.012,0.23,1.22,0.89,0.17,0.23,0.002,0.0103,0.0,0.0,27,525,680,19,64
665,0.18,0.39,0.63,0.012,0.012,0.23,1.22,0.89,0.17,0.23,0.002,0.0103,0.0,0.0,200,162,603,18,61
667,0.18,0.39,0.63,0.012,0.012,0.23,1.22,0.89,0.17,0.23,0.002,0.0103,0.0,0.0,400,473,587,14,51
669,0.18,0.39,0.63,0.012,0.012,0.23,1.22,0.89,0.17,0.23,0.002,0.0103,0.0,0.0,500,411,498,16,66
671,0.18,0.39,0.63,0.012,0.012,0.23,1.22,0.89,0.17,0.23,0.002,0.0103,0.0,0.0,600,323,386,25,81
673,0.15,0.52,0.78,0.01,0.009,0.12,1.17,0.98,0.08,0.23,0.003,0.0106,0.0,0.0,27,555,680,20,69
675,0.15,0.52,0.78,0.01,0.009,0.12,1.17,0.98,0.08,0.23,0.003,0.0106,0.0,0.0,200,501,619,18,70
677,0.15,0.52,0.78,0.01,0.009,0.12,1.17,0.98,0.08,0.23,0.003,0.0106,0.0,0.0,400,480,582,18,68
679,0.15,0.52,0.78,0.01,0.009,0.12,1.17,0.98,0.08,0.23,0.003,0.0106,0.0,0.0,500,433,505,19,75
681,0.15,0.52,0.78,0.01,0.009,0.12,1.17,0.98,0.08,0.23,0.003,0.0106,0.0,0.0,600,344,397,25,87
683,0.15,0.3,1.14,0.009,0.021,0.31,0.2,0.08,0.14,0.0,0.028,0.0082,0.42,0.0,27,468,592,25,73
685,0.15,0.3,1.14,0.009,0.021,0.31,0.2,0.08,0.14,0.0,0.028,0.0082,0.42,0.0,200,439,557,21,70
687,0.15,0.3,1.14,0.009,0.021,0.31,0.2,0.08,0.14,0.0,0.028,0.0082,0.42,0.0,350,403,566,28,69
689,0.15,0.3,1.14,0.009,0.021,0.31,0.2,0.08,0.14,0.0,0.028,0.0082,0.42,0.0,450,350,457,27,77
691,0.15,0.3,1.14,0.009,0.021,0.31,0.2,0.08,0.14,0.0,0.028,0.0082,0.42,0.0,550,271,344,29,74
693,0.15,0.28,1.32,0.019,0.005,0.077,0.053,0.008,0.08,0.07,0.017,0.0066,0.401,0.0,27,483,625,22,65
695,0.15,0.28,1.32,0.019,0.005,0.077,0.053,0.008,0.08,0.07,0.017,0.0066,0.401,0.0,200,450,623,19,61
697,0.15,0.28,1.32,0.019,0.005,0.077,0.053,0.008,0.08,0.07,0.017,0.0066,0.401,0.0,350,436,614,24,67
699,0.15,0.28,1.32,0.019,0.005,0.077,0.053,0.008,0.08,0.07,0.017,0.0066,0.401,0.0,450,375,490,27,74
701,0.15,0.28,1.32,0.019,0.005,0.077,0.053,0.008,0.08,0.07,0.017,0.0066,0.401,0.0,550,264,363,32,80
703,0.16,0.28,1.14,0.017,0.016,0.33,0.24,0.08,0.13,0.0,0.015,0.0067,0.437,0.0,27,590,692,21,68
705,0.16,0.28,1.14,0.017,0.016,0.33,0.24,0.08,0.13,0.0,0.015,0.0067,0.437,0.0,200,570,670,17,64
707,0.16,0.28,1.14,0.017,0.016,0.33,0.24,0.08,0.13,0.0,0.015,0.0067,0.437,0.0,350,526,659,23,66
709,0.16,0.28,1.14,0.017,0.016,0.33,0.24,0.08,0.13,0.0,0.015,0.0067,0.437,0.0,450,467,543,20,76
711,0.16,0.28,1.14,0.017,0.016,0.33,0.24,0.08,0.13,0.0,0.015,0.0067,0.437,0.0,550,288,387,20,68
713,0.16,0.48,1.21,0.017,0.009,0.02,0.02,0.1,0.02,0.05,0.04,0.0028,0.414,0.0,27,574,698,20,71
715,0.16,0.48,1.21,0.017,0.009,0.02,0.02,0.1,0.02,0.05,0.04,0.0028,0.414,0.0,200,513,641,19,70
717,0.16,0.48,1.21,0.017,0.009,0.02,0.02,0.1,0.02,0.05,0.04,0.0028,0.414,0.0,350,461,630,23,78
719,0.16,0.48,1.21,0.017,0.009,0.02,0.02,0.1,0.02,0.05,0.04,0.0028,0.414,0.0,450,424,535,23,82
721,0.16,0.48,1.21,0.017,0.009,0.02,0.02,0.1,0.02,0.05,0.04,0.0028,0.414,0.0,550,326,412,25,88
723,0.13,0.33,1.23,0.014,0.015,0.44,0.04,0.076,0.04,0.04,0.032,0.0074,0.389,0.0,27,515,629,24,71
725,0.13,0.33,1.23,0.014,0.015,0.44,0.04,0.076,0.04,0.04,0.032,0.0074,0.389,0.0,200,473,589,21,69
727,0.13,0.33,1.23,0.014,0.015,0.44,0.04,0.076,0.04,0.04,0.032,0.0074,0.389,0.0,350,446,595,26,72
729,0.13,0.33,1.23,0.014,0.015,0.44,0.04,0.076,0.04,0.04,0.032,0.0074,0.389,0.0,450,395,487,26,81
731,0.13,0.33,1.23,0.014,0.015,0.44,0.04,0.076,0.04,0.04,0.032,0.0074,0.389,0.0,550,298,367,33,84
733,0.14,0.3,1.09,0.008,0.015,0.39,0.12,0.09,0.17,0.0,0.032,0.0098,0.39,0.0,27,451,578,25,71
735,0.14,0.3,1.09,0.008,0.015,0.39,0.12,0.09,0.17,0.0,0.032,0.0098,0.39,0.0,200,411,533,21,68
737,0.14,0.3,1.09,0.008,0.015,0.39,0.12,0.09,0.17,0.0,0.032,0.0098,0.39,0.0,350,397,551,29,70
739,0.14,0.3,1.09,0.008,0.015,0.39,0.12,0.09,0.17,0.0,0.032,0.0098,0.39,0.0,450,342,432,27,73
741,0.14,0.3,1.09,0.008,0.015,0.39,0.12,0.09,0.17,0.0,0.032,0.0098,0.39,0.0,550,248,321,35,78
743,0.14,0.21,1.29,0.016,0.008,0.21,0.02,0.06,0.09,0.03,0.021,0.0065,0.39,0.0,27,476,604,20,70
745,0.14,0.21,1.29,0.016,0.008,0.21,0.02,0.06,0.09,0.03,0.021,0.0065,0.39,0.0,200,443,578,19,66
747,0.14,0.21,1.29,0.016,0.008,0.21,0.02,0.06,0.09,0.03,0.021,0.0065,0.39,0.0,350,409,582,21,66
749,0.14,0.21,1.29,0.016,0.008,0.21,0.02,0.06,0.09,0.03,0.021,0.0065,0.39,0.0,450,403,495,27,74
751,0.14,0.21,1.29,0.016,0.008,0.21,0.02,0.06,0.09,0.03,0.021,0.0065,0.39,0.0,550,299,374,31,80
753,0.148,0.49,1.27,0.03,0.005,0.04,0.19,0.02,0.03,0.07,0.036,0.0065,0.429,0.0,27,514,612,25,79
755,0.148,0.49,1.27,0.03,0.005,0.04,0.19,0.02,0.03,0.07,0.036,0.0065,0.429,0.0,200,511,599,20,76
757,0.148,0.49,1.27,0.03,0.005,0.04,0.19,0.02,0.03,0.07,0.036,0.0065,0.429,0.0,350,459,602,26,76
759,0.148,0.49,1.27,0.03,0.005,0.04,0.19,0.02,0.03,0.07,0.036,0.0065,0.429,0.0,450,388,491,30,84
761,0.148,0.49,1.27,0.03,0.005,0.04,0.19,0.02,0.03,0.07,0.036,0.0065,0.429,0.0,550,249,333,36,90
763,0.17,0.52,1.27,0.017,0.015,0.02,0.02,0.1,0.02,0.05,0.049,0.0026,0.436,0.0,27,623,736,19,70
765,0.17,0.52,1.27,0.017,0.015,0.02,0.02,0.1,0.02,0.05,0.049,0.0026,0.436,0.0,200,594,712,18,67
767,0.17,0.52,1.27,0.017,0.015,0.02,0.02,0.1,0.02,0.05,0.049,0.0026,0.436,0.0,350,517,660,20,76
769,0.17,0.52,1.27,0.017,0.015,0.02,0.02,0.1,0.02,0.05,0.049,0.0026,0.436,0.0,450,483,576,19,81
771,0.17,0.52,1.27,0.017,0.015,0.02,0.02,0.1,0.02,0.05,0.049,0.0026,0.436,0.0,550,368,464,22,87
773,0.12,0.33,1.37,0.016,0.012,0.19,0.03,0.01,0.03,0.08,0.042,0.007,0.381,0.0,27,666,676,23,70
775,0.12,0.33,1.37,0.016,0.012,0.19,0.03,0.01,0.03,0.08,0.042,0.007,0.381,0.0,200,507,630,19,68
777,0.12,0.33,1.37,0.016,0.012,0.19,0.03,0.01,0.03,0.08,0.042,0.007,0.381,0.0,350,467,630,28,75
779,0.12,0.33,1.37,0.016,0.012,0.19,0.03,0.01,0.03,0.08,0.042,0.007,0.381,0.0,450,409,517,28,79
781,0.12,0.33,1.37,0.016,0.012,0.19,0.03,0.01,0.03,0.08,0.042,0.007,0.381,0.0,550,281,382,30,82
783,0.13,0.34,1.23,0.012,0.016,0.46,0.03,0.072,0.02,0.042,0.035,0.0065,0.387,0.0,27,533,636,24,72
785,0.13,0.34,1.23,0.012,0.016,0.46,0.03,0.072,0.02,0.042,0.035,0.0065,0.387,0.0,200,482,602,19,67
787,0.13,0.34,1.23,0.012,0.016,0.46,0.03,0.072,0.02,0.042,0.035,0.0065,0.387,0.0,350,437,609,27,76
789,0.13,0.34,1.23,0.012,0.016,0.46,0.03,0.072,0.02,0.042,0.035,0.0065,0.387,0.0,450,396,496,26,83
791,0.13,0.34,1.23,0.012,0.016,0.46,0.03,0.072,0.02,0.042,0.035,0.0065,0.387,0.0,550,301,376,33,85
793,0.12,0.37,1.32,0.012,0.012,0.22,0.03,0.07,0.07,0.04,0.03,0.0064,0.387,0.0,27,455,571,28,75
795,0.12,0.37,1.32,0.012,0.012,0.22,0.03,0.07,0.07,0.04,0.03,0.0064,0.387,0.0,200,394,530,23,72
797,0.12,0.37,1.32,0.012,0.012,0.22,0.03,0.07,0.07,0.04,0.03,0.0064,0.387,0.0,350,357,562,30,74
799,0.12,0.37,1.32,0.012,0.012,0.22,0.03,0.07,0.07,0.04,0.03,0.0064,0.387,0.0,450,321,450,32,78
801,0.12,0.37,1.32,0.012,0.012,0.22,0.03,0.07,0.07,0.04,0.03,0.0064,0.387,0.0,550,244,326,39,85
803,0.16,0.29,1.42,0.013,0.006,0.041,0.054,0.011,0.08,0.079,0.006,0.0048,0.429,0.0,27,501,630,24,72
805,0.16,0.29,1.42,0.013,0.006,0.041,0.054,0.011,0.08,0.079,0.006,0.0048,0.429,0.0,200,482,636,20,70
807,0.16,0.29,1.42,0.013,0.006,0.041,0.054,0.011,0.08,0.079,0.006,0.0048,0.429,0.0,350,451,623,25,75
809,0.16,0.29,1.42,0.013,0.006,0.041,0.054,0.011,0.08,0.079,0.006,0.0048,0.429,0.0,450,388,505,27,81
811,0.16,0.29,1.42,0.013,0.006,0.041,0.054,0.011,0.08,0.079,0.006,0.0048,0.429,0.0,550,251,343,27,89
813,0.123,0.44,1.19,0.021,0.006,0.05,0.2,0.02,0.03,0.07,0.04,0.006,0.39,0.0,27,530,630,24,77
815,0.123,0.44,1.19,0.021,0.006,0.05,0.2,0.02,0.03,0.07,0.04,0.006,0.39,0.0,200,465,570,21,77
817,0.123,0.44,1.19,0.021,0.006,0.05,0.2,0.02,0.03,0.07,0.04,0.006,0.39,0.0,350,451,598,29,81
819,0.123,0.44,1.19,0.021,0.006,0.05,0.2,0.02,0.03,0.07,0.04,0.006,0.39,0.0,450,383,475,31,84
821,0.123,0.44,1.19,0.021,0.006,0.05,0.2,0.02,0.03,0.07,0.04,0.006,0.39,0.0,550,276,364,39,90
823,0.14,0.38,1.24,0.014,0.014,0.43,0.03,0.084,0.05,0.043,0.04,0.0066,0.403,0.0,27,539,648,24,72
825,0.14,0.38,1.24,0.014,0.014,0.43,0.03,0.084,0.05,0.043,0.04,0.0066,0.403,0.0,200,497,609,19,70
827,0.14,0.38,1.24,0.014,0.014,0.43,0.03,0.084,0.05,0.043,0.04,0.0066,0.403,0.0,350,447,609,25,75
829,0.14,0.38,1.24,0.014,0.014,0.43,0.03,0.084,0.05,0.043,0.04,0.0066,0.403,0.0,450,403,503,23,79
831,0.14,0.38,1.24,0.014,0.014,0.43,0.03,0.084,0.05,0.043,0.04,0.0066,0.403,0.0,550,313,378,25,85
833,0.14,0.33,1.45,0.025,0.012,0.18,0.03,0.01,0.02,0.06,0.05,0.0051,0.412,0.0,27,513,660,22,71
835,0.14,0.33,1.45,0.025,0.012,0.18,0.03,0.01,0.02,0.06,0.05,0.0051,0.412,0.0,200,500,616,20,65
837,0.14,0.33,1.45,0.025,0.012,0.18,0.03,0.01,0.02,0.06,0.05,0.0051,0.412,0.0,350,469,630,25,71
839,0.14,0.33,1.45,0.025,0.012,0.18,0.03,0.01,0.02,0.06,0.05,0.0051,0.412,0.0,450,402,509,27,82
841,0.14,0.33,1.45,0.025,0.012,0.18,0.03,0.01,0.02,0.06,0.05,0.0051,0.412,0.0,550,278,367,36,89
843,0.15,0.25,1.38,0.014,0.006,0.04,0.041,0.006,0.08,0.088,0.015,0.0076,0.407,0.0,27,483,618,23,71
845,0.15,0.25,1.38,0.014,0.006,0.04,0.041,0.006,0.08,0.088,0.015,0.0076,0.407,0.0,200,411,585,22,68
847,0.15,0.25,1.38,0.014,0.006,0.04,0.041,0.006,0.08,0.088,0.015,0.0076,0.407,0.0,350,395,573,24,68
849,0.15,0.25,1.38,0.014,0.006,0.04,0.041,0.006,0.08,0.088,0.015,0.0076,0.407,0.0,450,312,442,28,75
851,0.15,0.25,1.38,0.014,0.006,0.04,0.041,0.006,0.08,0.088,0.015,0.0076,0.407,0.0,550,229,330,39,78
853,0.143,0.5,1.2,0.03,0.007,0.06,0.17,0.02,0.02,0.07,0.029,0.0068,0.409,0.0,27,488,601,27,77
855,0.143,0.5,1.2,0.03,0.007,0.06,0.17,0.02,0.02,0.07,0.029,0.0068,0.409,0.0,200,445,585,22,72
857,0.143,0.5,1.2,0.03,0.007,0.06,0.17,0.02,0.02,0.07,0.029,0.0068,0.409,0.0,350,420,599,28,76
859,0.143,0.5,1.2,0.03,0.007,0.06,0.17,0.02,0.02,0.07,0.029,0.0068,0.409,0.0,450,356,468,32,84
861,0.143,0.5,1.2,0.03,0.007,0.06,0.17,0.02,0.02,0.07,0.029,0.0068,0.409,0.0,550,256,328,46,91
863,0.17,0.49,1.26,0.013,0.01,0.01,0.02,0.09,0.02,0.04,0.045,0.0025,0.429,0.0,27,537,672,22,71
865,0.17,0.49,1.26,0.013,0.01,0.01,0.02,0.09,0.02,0.04,0.045,0.0025,0.429,0.0,200,532,666,18,68
867,0.17,0.49,1.26,0.013,0.01,0.01,0.02,0.09,0.02,0.04,0.045,0.0025,0.429,0.0,350,465,632,26,80
869,0.17,0.49,1.26,0.013,0.01,0.01,0.02,0.09,0.02,0.04,0.045,0.0025,0.429,0.0,450,411,519,24,83
871,0.17,0.49,1.26,0.013,0.01,0.01,0.02,0.09,0.02,0.04,0.045,0.0025,0.429,0.0,550,335,415,24,87
873,0.13,0.42,1.28,0.014,0.012,0.21,0.22,0.05,0.04,0.03,0.037,0.0072,0.424,0.0,27,476,603,27,76
875,0.13,0.42,1.28,0.014,0.012,0.21,0.22,0.05,0.04,0.03,0.037,0.0072,0.424,0.0,200,426,569,24,74
877,0.13,0.42,1.28,0.014,0.012,0.21,0.22,0.05,0.04,0.03,0.037,0.0072,0.424,0.0,350,391,580,29,75
879,0.13,0.42,1.28,0.014,0.012,0.21,0.22,0.05,0.04,0.03,0.037,0.0072,0.424,0.0,450,359,473,30,82
881,0.13,0.42,1.28,0.014,0.012,0.21,0.22,0.05,0.04,0.03,0.037,0.0072,0.424,0.0,550,253,341,38,84
883,0.16,0.41,1.48,0.014,0.01,0.02,0.02,0.01,0.03,0.08,0.033,0.0079,0.436,0.0,27,577,693,20,62
885,0.16,0.41,1.48,0.014,0.01,0.02,0.02,0.01,0.03,0.08,0.033,0.0079,0.436,0.0,200,542,679,18,60
887,0.16,0.41,1.48,0.014,0.01,0.02,0.02,0.01,0.03,0.08,0.033,0.0079,0.436,0.0,350,487,655,25,66
889,0.16,0.41,1.48,0.014,0.01,0.02,0.02,0.01,0.03,0.08,0.033,0.0079,0.436,0.0,450,404,513,25,78
891,0.16,0.41,1.48,0.014,0.01,0.02,0.02,0.01,0.03,0.08,0.033,0.0079,0.436,0.0,550,27,375,38,81
893,0.23,0.23,1.23,0.027,0.012,0.03,0.04,0.017,0.01,0.009,0.003,0.0111,0.0,0.0017,27,359,578,27,70
895,0.23,0.23,1.23,0.027,0.012,0.03,0.04,0.017,0.01,0.009,0.003,0.0111,0.0,0.0017,150,367,651,16,51
897,0.23,0.23,1.23,0.027,0.012,0.03,0.04,0.017,0.01,0.009,0.003,0.0111,0.0,0.0017,250,305,696,22,49
899,0.23,0.23,1.23,0.027,0.012,0.03,0.04,0.017,0.01,0.009,0.003,0.0111,0.0,0.0017,350,258,627,30,65
901,0.23,0.23,1.23,0.027,0.012,0.03,0.04,0.017,0.01,0.009,0.003,0.0111,0.0,0.0017,450,240,498,30,72
903,0.23,0.23,1.23,0.027,0.012,0.03,0.04,0.017,0.01,0.009,0.003,0.0111,0.0,0.0017,550,203,320,40,86
905,0.22,0.22,1.24,0.021,0.008,0.03,0.05,0.017,0.01,0.005,0.005,0.0116,0.0,0.0017,100,381,561,22,66
907,0.22,0.22,1.24,0.021,0.008,0.03,0.05,0.017,0.01,0.005,0.005,0.0116,0.0,0.0017,200,396,705,16,47
909,0.22,0.22,1.24,0.021,0.008,0.03,0.05,0.017,0.01,0.005,0.005,0.0116,0.0,0.0017,300,282,682,27,56
911,0.22,0.22,1.24,0.021,0.008,0.03,0.05,0.017,0.01,0.005,0.005,0.0116,0.0,0.0017,400,244,575,28,68
913,0.22,0.22,1.24,0.021,0.008,0.03,0.05,0.017,0.01,0.005,0.005,0.0116,0.0,0.0017,500,209,428,30,78
914,0.22,0.22,1.24,0.021,0.008,0.03,0.05,0.017,0.01,0.005,0.005,0.0116,0.0,0.0017,550,200,328,40,86